Workbook

Sheet Ringkasan
A1: Ringkasan run - audit lintas sumber
A3: Mint | B3: 9U1f18idDeySFnYrurxqT1f5n5nE4g4Uk5LLzP69bh1
A4: Waktu snapshot (UTC) | B4: 2026-10-15 07:14:27
A5: Sumber diminta | B5: Vybe, SolanaTracker, GMGN
A6: Sumber berhasil | B6: 1 dari 3 (SolanaTracker)
A7: Versi suite / Python | B7: 1.0.0 / 3.14.6
A9: Parameter (sel kuning boleh diubah; kolom flag_spread di sheet Gabungan dan hitungannya di sini ikut dihitung ulang)
A10: Ambang selisih realized (USD) >= | B10: 10
A11: Ambang selisih relatif >= | B11: 0.25
A12: Nilai awal berasal dari argumen --spread-usd dan --spread-pct. Selisih relatif = (tertinggi - terendah) / nilai absolut terbesar.
A14: Status per sumber
A15: Sumber | B15: Status | C15: Baris | D15: Mulai (UTC) | E15: Selesai (UTC) | F15: Durasi (dtk) | G15: Aktivitas terbaru di daftar (UTC) | H15: Selisih ke waktu selesai (menit) | I15: Aktivitas tertua di daftar (UTC) | J15: Catatan
A16: Vybe | B16: gagal | D16: 2026-10-15 07:14:27 | E16: 2026-10-15 07:14:29 | F16: 2.1 | J16: Error: Vybe returned no traders for this token.
A17: SolanaTracker | B17: ok | C17: 100 | D17: 2026-10-15 07:14:27 | E17: 2026-10-15 07:14:30 | F17: 2.6 | G17: 2026-10-13 15:38:23 | H17: 2376.1 | I17: 2026-09-17 19:12:08
A18: GMGN | B18: gagal | D18: 2026-10-15 07:14:27 | E18: 2026-10-15 07:14:29 | F18: 2 | J18: Error: GMGN API error (HTTP 401): code=401 AUTH_TIMESTAMP_EXPIRED timestamp expired Check GMGN_API_KEY (the API key, not the private key). GMGN only works over IPv4, so disable IPv6 if the key is correct, and make sure this PC's clock is accurate (the server allows about 5 seconds of drift).
A19: 'Aktivitas terbaru/tertua' hanya dari wallet yang ada di daftar (bukan seluruh token), jadi menunjukkan perkiraan kasar keterlambatan data.
A20: Aktivitas tertua yang terlihat: 2026-09-17 19:12:08 UTC (sekitar 660.04 jam sebelum snapshot).
A22: Catatan
A23: Yang dibandingkan hanya realized PnL. Unrealized bergantung pada harga yang dipakai tiap provider saat menghitung, jadi hanya indikatif dan tidak dinilai selisihnya.
A24: Hanya satu sumber yang berhasil, jadi perbandingan lintas sumber tidak tersedia.
A25: SolanaTracker mengembalikan 100 baris (batas 100). Wallet di luar daftar tidak terlihat, jadi 'hanya di satu sumber' bisa disebabkan daftar yang terpotong.
A27: Kamus kolom sheet Gabungan
A28: rank_*: peringkat wallet di CSV provider itu (urutan realized PnL); kosong = wallet tidak ada di daftar provider itu.
A29: realized_*: realized_pnl_usd apa adanya dari provider; tidak ada rata-rata dan tidak ada penyatuan definisi.
A30: n_sources, spread_usd, spread_pct, flag_spread: rumus Excel. spread = realized tertinggi dikurangi terendah di antara provider yang memuat wallet.
A31: only_in: provider yang satu-satunya memuat wallet (hanya diisi bila >= 2 provider berhasil). Waspada: bisa karena daftar terpotong.
A32: role_disagreement: peran (dev, kol, smart_money, sniper, bundler, bot, arbitrage, pool_or_exchange) yang hanya dimiliki sebagian provider. Pemetaan label sederhana di suite/labels.py; hanya provider yang memberi label pada setidaknya satu wallet di run ini yang dibandingkan.
A33: sheet_row_*: nomor baris wallet di sheet mentah provider itu, untuk menelusuri angka ke sumbernya.

Sheet Gabungan
A1: wallet | B1: name | C1: n_sources | D1: sources | E1: rank_vybe | F1: rank_solanatracker | G1: rank_gmgn | H1: realized_vybe | I1: realized_solanatracker | J1: realized_gmgn | K1: spread_usd | L1: spread_pct | M1: flag_spread | N1: only_in | O1: role_disagreement | P1: labels_vybe | Q1: labels_solanatracker | R1: labels_gmgn | S1: funded_by_gmgn | T1: sheet_row_vybe | U1: sheet_row_solanatracker | V1: sheet_row_gmgn
A2: 3jvB7JMR7QhTqohucrQqiB6UPazbB8e2Zo6mQSKDCCGq | B2: SandySulkyFruit | C2: =COUNT(E2:G2) | D2: SolanaTracker | F2: 1 | I2: 20801.32 | K2: =IF(COUNT(H2:J2)>=2,MAX(H2:J2)-MIN(H2:J2),"") | L2: =IF(ISNUMBER(K2),IF(MAX(ABS(MAX(H2:J2)),ABS(MIN(H2:J2)))=0,"",K2/MAX(ABS(MAX(H2:J2)),ABS(MIN(H2:J2)))),"") | M2: =IF(AND(ISNUMBER(K2),ISNUMBER(L2)),IF(AND(K2>=Ringkasan!$B$10,L2>=Ringkasan!$B$11),"yes",""),"") | Q2: gmgn; axiom; pumpfun-app; bloom | U2: 2
A3: AYZryL5JYFhAJ7PtA9uvebDqcFrifcPTucvDyjbd7xzN | C3: =COUNT(E3:G3) | D3: SolanaTracker | F3: 2 | I3: 18694.13 | K3: =IF(COUNT(H3:J3)>=2,MAX(H3:J3)-MIN(H3:J3),"") | L3: =IF(ISNUMBER(K3),IF(MAX(ABS(MAX(H3:J3)),ABS(MIN(H3:J3)))=0,"",K3/MAX(ABS(MAX(H3:J3)),ABS(MIN(H3:J3)))),"") | M3: =IF(AND(ISNUMBER(K3),ISNUMBER(L3)),IF(AND(K3>=Ringkasan!$B$10,L3>=Ringkasan!$B$11),"yes",""),"") | Q3: terminal; axiom | U3: 3
A4: 4CwrH924ZreiA4rjEfWRbVa28LrzYb18EBjGhLLZwBjX | B4: Spoily | C4: =COUNT(E4:G4) | D4: SolanaTracker | F4: 3 | I4: 18640.15 | K4: =IF(COUNT(H4:J4)>=2,MAX(H4:J4)-MIN(H4:J4),"") | L4: =IF(ISNUMBER(K4),IF(MAX(ABS(MAX(H4:J4)),ABS(MIN(H4:J4)))=0,"",K4/MAX(ABS(MAX(H4:J4)),ABS(MIN(H4:J4)))),"") | M4: =IF(AND(ISNUMBER(K4),ISNUMBER(L4)),IF(AND(K4>=Ringkasan!$B$10,L4>=Ringkasan!$B$11),"yes",""),"") | Q4: potential_bot; fomo | U4: 4
A5: 8Hh4H35D498baNnWXdsAct6pj5LtnkNS1Xi8KtQq6huK | B5: Saif | C5: =COUNT(E5:G5) | D5: SolanaTracker | F5: 4 | I5: 15226.57 | K5: =IF(COUNT(H5:J5)>=2,MAX(H5:J5)-MIN(H5:J5),"") | L5: =IF(ISNUMBER(K5),IF(MAX(ABS(MAX(H5:J5)),ABS(MIN(H5:J5)))=0,"",K5/MAX(ABS(MAX(H5:J5)),ABS(MIN(H5:J5)))),"") | M5: =IF(AND(ISNUMBER(K5),ISNUMBER(L5)),IF(AND(K5>=Ringkasan!$B$10,L5>=Ringkasan!$B$11),"yes",""),"") | Q5: fomo | U5: 5
A6: EJFEveW2fy9o7ARLpU7ch7aHbPwK3hLKGTmQ9EkNZa43 | B6: FirmDeafFox | C6: =COUNT(E6:G6) | D6: SolanaTracker | F6: 5 | I6: 14197.44 | K6: =IF(COUNT(H6:J6)>=2,MAX(H6:J6)-MIN(H6:J6),"") | L6: =IF(ISNUMBER(K6),IF(MAX(ABS(MAX(H6:J6)),ABS(MIN(H6:J6)))=0,"",K6/MAX(ABS(MAX(H6:J6)),ABS(MIN(H6:J6)))),"") | M6: =IF(AND(ISNUMBER(K6),ISNUMBER(L6)),IF(AND(K6>=Ringkasan!$B$10,L6>=Ringkasan!$B$11),"yes",""),"") | Q6: fomo | U6: 6
A7: 4nQ4VWTAadJB2sgQqabBVBft3VPpQcHi3RdX2qcJZTMD | C7: =COUNT(E7:G7) | D7: SolanaTracker | F7: 6 | I7: 11818.44 | K7: =IF(COUNT(H7:J7)>=2,MAX(H7:J7)-MIN(H7:J7),"") | L7: =IF(ISNUMBER(K7),IF(MAX(ABS(MAX(H7:J7)),ABS(MIN(H7:J7)))=0,"",K7/MAX(ABS(MAX(H7:J7)),ABS(MIN(H7:J7)))),"") | M7: =IF(AND(ISNUMBER(K7),ISNUMBER(L7)),IF(AND(K7>=Ringkasan!$B$10,L7>=Ringkasan!$B$11),"yes",""),"") | Q7: axiom | U7: 7
A8: 3ULrdcEaBHsXACWnMo6foav1nkV7QDsPipsUyY2fT5AS | B8: newlobster60567 | C8: =COUNT(E8:G8) | D8: SolanaTracker | F8: 7 | I8: 11324.02 | K8: =IF(COUNT(H8:J8)>=2,MAX(H8:J8)-MIN(H8:J8),"") | L8: =IF(ISNUMBER(K8),IF(MAX(ABS(MAX(H8:J8)),ABS(MIN(H8:J8)))=0,"",K8/MAX(ABS(MAX(H8:J8)),ABS(MIN(H8:J8)))),"") | M8: =IF(AND(ISNUMBER(K8),ISNUMBER(L8)),IF(AND(K8>=Ringkasan!$B$10,L8>=Ringkasan!$B$11),"yes",""),"") | Q8: potential_bot; pumpfun-app | U8: 8
A9: CyaE1VxvBrahnPWkqm5VsdCvyS2QmNht2UFrKJHga54o | B9: Cented | C9: =COUNT(E9:G9) | D9: SolanaTracker | F9: 8 | I9: 10423.99 | K9: =IF(COUNT(H9:J9)>=2,MAX(H9:J9)-MIN(H9:J9),"") | L9: =IF(ISNUMBER(K9),IF(MAX(ABS(MAX(H9:J9)),ABS(MIN(H9:J9)))=0,"",K9/MAX(ABS(MAX(H9:J9)),ABS(MIN(H9:J9)))),"") | M9: =IF(AND(ISNUMBER(K9),ISNUMBER(L9)),IF(AND(K9>=Ringkasan!$B$10,L9>=Ringkasan!$B$11),"yes",""),"") | Q9: kol; terminal; axiom; photon; pumpfun-app; bloom; sns | U9: 9
A10: 5B79fMkcFeRTiwm7ehsZsFiKsC7m7n1Bgv9yLxPp9q2X | B10: bandit | C10: =COUNT(E10:G10) | D10: SolanaTracker | F10: 9 | I10: 10400.93 | K10: =IF(COUNT(H10:J10)>=2,MAX(H10:J10)-MIN(H10:J10),"") | L10: =IF(ISNUMBER(K10),IF(MAX(ABS(MAX(H10:J10)),ABS(MIN(H10:J10)))=0,"",K10/MAX(ABS(MAX(H10:J10)),ABS(MIN(H10:J10)))),"") | M10: =IF(AND(ISNUMBER(K10),ISNUMBER(L10)),IF(AND(K10>=Ringkasan!$B$10,L10>=Ringkasan!$B$11),"yes",""),"") | Q10: kol; axiom; sns | U10: 10
A11: EYkRnmNfmSFUkzz4vYE2uii2UW2cTSr2Urf32BUkUX9k | C11: =COUNT(E11:G11) | D11: SolanaTracker | F11: 10 | I11: 9666.4 | K11: =IF(COUNT(H11:J11)>=2,MAX(H11:J11)-MIN(H11:J11),"") | L11: =IF(ISNUMBER(K11),IF(MAX(ABS(MAX(H11:J11)),ABS(MIN(H11:J11)))=0,"",K11/MAX(ABS(MAX(H11:J11)),ABS(MIN(H11:J11)))),"") | M11: =IF(AND(ISNUMBER(K11),ISNUMBER(L11)),IF(AND(K11>=Ringkasan!$B$10,L11>=Ringkasan!$B$11),"yes",""),"") | U11: 11
A12: 3nLh14fRyZr1EBpp7jJqwBqKt8uLBFZ1rTmVTfLvnkfj | C12: =COUNT(E12:G12) | D12: SolanaTracker | F12: 11 | I12: 9051.79 | K12: =IF(COUNT(H12:J12)>=2,MAX(H12:J12)-MIN(H12:J12),"") | L12: =IF(ISNUMBER(K12),IF(MAX(ABS(MAX(H12:J12)),ABS(MIN(H12:J12)))=0,"",K12/MAX(ABS(MAX(H12:J12)),ABS(MIN(H12:J12)))),"") | M12: =IF(AND(ISNUMBER(K12),ISNUMBER(L12)),IF(AND(K12>=Ringkasan!$B$10,L12>=Ringkasan!$B$11),"yes",""),"") | Q12: potential_bot; axiom | U12: 12
A13: 5tNXmLdWCY58mjGVn6a6hTxLqyDntKAetwWcLaphRnL | C13: =COUNT(E13:G13) | D13: SolanaTracker | F13: 12 | I13: 8497.26 | K13: =IF(COUNT(H13:J13)>=2,MAX(H13:J13)-MIN(H13:J13),"") | L13: =IF(ISNUMBER(K13),IF(MAX(ABS(MAX(H13:J13)),ABS(MIN(H13:J13)))=0,"",K13/MAX(ABS(MAX(H13:J13)),ABS(MIN(H13:J13)))),"") | M13: =IF(AND(ISNUMBER(K13),ISNUMBER(L13)),IF(AND(K13>=Ringkasan!$B$10,L13>=Ringkasan!$B$11),"yes",""),"") | Q13: axiom | U13: 13
A14: WJWQRpigXNgnMH8wdjLuo5XfuY3sk6WHc3DAaBXf8Vx | C14: =COUNT(E14:G14) | D14: SolanaTracker | F14: 13 | I14: 7679.67 | K14: =IF(COUNT(H14:J14)>=2,MAX(H14:J14)-MIN(H14:J14),"") | L14: =IF(ISNUMBER(K14),IF(MAX(ABS(MAX(H14:J14)),ABS(MIN(H14:J14)))=0,"",K14/MAX(ABS(MAX(H14:J14)),ABS(MIN(H14:J14)))),"") | M14: =IF(AND(ISNUMBER(K14),ISNUMBER(L14)),IF(AND(K14>=Ringkasan!$B$10,L14>=Ringkasan!$B$11),"yes",""),"") | Q14: axiom | U14: 14
A15: 922M9fBTzwGfC4Gqu3WxB8S89WHaTfVAUZKwK5PNtZpk | C15: =COUNT(E15:G15) | D15: SolanaTracker | F15: 14 | I15: 7145.46 | K15: =IF(COUNT(H15:J15)>=2,MAX(H15:J15)-MIN(H15:J15),"") | L15: =IF(ISNUMBER(K15),IF(MAX(ABS(MAX(H15:J15)),ABS(MIN(H15:J15)))=0,"",K15/MAX(ABS(MAX(H15:J15)),ABS(MIN(H15:J15)))),"") | M15: =IF(AND(ISNUMBER(K15),ISNUMBER(L15)),IF(AND(K15>=Ringkasan!$B$10,L15>=Ringkasan!$B$11),"yes",""),"") | Q15: potential_bot | U15: 15
A16: HyGWBXCTcSW3F9dPdZhz5RD4ubjKyjmMccArDSEBfYxM | C16: =COUNT(E16:G16) | D16: SolanaTracker | F16: 15 | I16: 6992.96 | K16: =IF(COUNT(H16:J16)>=2,MAX(H16:J16)-MIN(H16:J16),"") | L16: =IF(ISNUMBER(K16),IF(MAX(ABS(MAX(H16:J16)),ABS(MIN(H16:J16)))=0,"",K16/MAX(ABS(MAX(H16:J16)),ABS(MIN(H16:J16)))),"") | M16: =IF(AND(ISNUMBER(K16),ISNUMBER(L16)),IF(AND(K16>=Ringkasan!$B$10,L16>=Ringkasan!$B$11),"yes",""),"") | Q16: terminal; axiom | U16: 16
A17: 5pHeNsWMVEi1cbMzLhgqABnhEUwRTSzy5vBfeGWyJfxS | B17: ‎ ‎ ‎ | C17: =COUNT(E17:G17) | D17: SolanaTracker | F17: 16 | I17: 6435.1 | K17: =IF(COUNT(H17:J17)>=2,MAX(H17:J17)-MIN(H17:J17),"") | L17: =IF(ISNUMBER(K17),IF(MAX(ABS(MAX(H17:J17)),ABS(MIN(H17:J17)))=0,"",K17/MAX(ABS(MAX(H17:J17)),ABS(MIN(H17:J17)))),"") | M17: =IF(AND(ISNUMBER(K17),ISNUMBER(L17)),IF(AND(K17>=Ringkasan!$B$10,L17>=Ringkasan!$B$11),"yes",""),"") | Q17: potential_bot; fomo | U17: 17
A18: 6dC4Rvt1c6mv6M27QeAxRCCbXjUaZPFRZPxZn2rLXN7s | C18: =COUNT(E18:G18) | D18: SolanaTracker | F18: 17 | I18: 6405.29 | K18: =IF(COUNT(H18:J18)>=2,MAX(H18:J18)-MIN(H18:J18),"") | L18: =IF(ISNUMBER(K18),IF(MAX(ABS(MAX(H18:J18)),ABS(MIN(H18:J18)))=0,"",K18/MAX(ABS(MAX(H18:J18)),ABS(MIN(H18:J18)))),"") | M18: =IF(AND(ISNUMBER(K18),ISNUMBER(L18)),IF(AND(K18>=Ringkasan!$B$10,L18>=Ringkasan!$B$11),"yes",""),"") | Q18: potential_bot; gmgn; axiom | U18: 18
A19: 1CNg1DM3egT1qiHNFNFNAFsCmgpczHHJk2fZdnkJyUv | C19: =COUNT(E19:G19) | D19: SolanaTracker | F19: 18 | I19: 6014.38 | K19: =IF(COUNT(H19:J19)>=2,MAX(H19:J19)-MIN(H19:J19),"") | L19: =IF(ISNUMBER(K19),IF(MAX(ABS(MAX(H19:J19)),ABS(MIN(H19:J19)))=0,"",K19/MAX(ABS(MAX(H19:J19)),ABS(MIN(H19:J19)))),"") | M19: =IF(AND(ISNUMBER(K19),ISNUMBER(L19)),IF(AND(K19>=Ringkasan!$B$10,L19>=Ringkasan!$B$11),"yes",""),"") | Q19: potential_bot; terminal; axiom | U19: 19
A20: 8HH3M6SfUCC9yGM3ytaFQWnDc19tSBYCNJBnqeWaQ8Xb | B20: fomo_sexual | C20: =COUNT(E20:G20) | D20: SolanaTracker | F20: 19 | I20: 5839.45 | K20: =IF(COUNT(H20:J20)>=2,MAX(H20:J20)-MIN(H20:J20),"") | L20: =IF(ISNUMBER(K20),IF(MAX(ABS(MAX(H20:J20)),ABS(MIN(H20:J20)))=0,"",K20/MAX(ABS(MAX(H20:J20)),ABS(MIN(H20:J20)))),"") | M20: =IF(AND(ISNUMBER(K20),ISNUMBER(L20)),IF(AND(K20>=Ringkasan!$B$10,L20>=Ringkasan!$B$11),"yes",""),"") | Q20: pumpfun-app | U20: 20
A21: 3EmnFHt5dFo5RW4oJf4zruBKJtm2gNgTkGCB5n6dXDvf | C21: =COUNT(E21:G21) | D21: SolanaTracker | F21: 20 | I21: 5696.76 | K21: =IF(COUNT(H21:J21)>=2,MAX(H21:J21)-MIN(H21:J21),"") | L21: =IF(ISNUMBER(K21),IF(MAX(ABS(MAX(H21:J21)),ABS(MIN(H21:J21)))=0,"",K21/MAX(ABS(MAX(H21:J21)),ABS(MIN(H21:J21)))),"") | M21: =IF(AND(ISNUMBER(K21),ISNUMBER(L21)),IF(AND(K21>=Ringkasan!$B$10,L21>=Ringkasan!$B$11),"yes",""),"") | Q21: fomo | U21: 21
A22: gasBidSWW5zmwXs3gn8TG2ijzKkrwpyM7ucwjgDQst6 | C22: =COUNT(E22:G22) | D22: SolanaTracker | F22: 21 | I22: 5684.03 | K22: =IF(COUNT(H22:J22)>=2,MAX(H22:J22)-MIN(H22:J22),"") | L22: =IF(ISNUMBER(K22),IF(MAX(ABS(MAX(H22:J22)),ABS(MIN(H22:J22)))=0,"",K22/MAX(ABS(MAX(H22:J22)),ABS(MIN(H22:J22)))),"") | M22: =IF(AND(ISNUMBER(K22),ISNUMBER(L22)),IF(AND(K22>=Ringkasan!$B$10,L22>=Ringkasan!$B$11),"yes",""),"") | Q22: potential_bot | U22: 22
A23: 2tiFfUNd4HEYg5XtSiNgrfptZ5LSjNU4dCFbg5YqWbBz | C23: =COUNT(E23:G23) | D23: SolanaTracker | F23: 22 | I23: 5145.71 | K23: =IF(COUNT(H23:J23)>=2,MAX(H23:J23)-MIN(H23:J23),"") | L23: =IF(ISNUMBER(K23),IF(MAX(ABS(MAX(H23:J23)),ABS(MIN(H23:J23)))=0,"",K23/MAX(ABS(MAX(H23:J23)),ABS(MIN(H23:J23)))),"") | M23: =IF(AND(ISNUMBER(K23),ISNUMBER(L23)),IF(AND(K23>=Ringkasan!$B$10,L23>=Ringkasan!$B$11),"yes",""),"") | Q23: gmgn; axiom | U23: 23
A24: nMK9myLJSftWpbacFUnaHx5bG3VUmbucghQMyHMgFZU | C24: =COUNT(E24:G24) | D24: SolanaTracker | F24: 23 | I24: 5109.42 | K24: =IF(COUNT(H24:J24)>=2,MAX(H24:J24)-MIN(H24:J24),"") | L24: =IF(ISNUMBER(K24),IF(MAX(ABS(MAX(H24:J24)),ABS(MIN(H24:J24)))=0,"",K24/MAX(ABS(MAX(H24:J24)),ABS(MIN(H24:J24)))),"") | M24: =IF(AND(ISNUMBER(K24),ISNUMBER(L24)),IF(AND(K24>=Ringkasan!$B$10,L24>=Ringkasan!$B$11),"yes",""),"") | Q24: axiom | U24: 24
A25: 4xd3Y2qvX43wwfLupdQVsE5ZTpnhXmpn8Dmf4Hufkj9n | C25: =COUNT(E25:G25) | D25: SolanaTracker | F25: 24 | I25: 4729 | K25: =IF(COUNT(H25:J25)>=2,MAX(H25:J25)-MIN(H25:J25),"") | L25: =IF(ISNUMBER(K25),IF(MAX(ABS(MAX(H25:J25)),ABS(MIN(H25:J25)))=0,"",K25/MAX(ABS(MAX(H25:J25)),ABS(MIN(H25:J25)))),"") | M25: =IF(AND(ISNUMBER(K25),ISNUMBER(L25)),IF(AND(K25>=Ringkasan!$B$10,L25>=Ringkasan!$B$11),"yes",""),"") | Q25: axiom | U25: 25
A26: DXYo85dMRjN72mEwwMADfPcsSknup9D7aoH9TExCDpns | B26: robustorca18145 | C26: =COUNT(E26:G26) | D26: SolanaTracker | F26: 25 | I26: 4724.37 | K26: =IF(COUNT(H26:J26)>=2,MAX(H26:J26)-MIN(H26:J26),"") | L26: =IF(ISNUMBER(K26),IF(MAX(ABS(MAX(H26:J26)),ABS(MIN(H26:J26)))=0,"",K26/MAX(ABS(MAX(H26:J26)),ABS(MIN(H26:J26)))),"") | M26: =IF(AND(ISNUMBER(K26),ISNUMBER(L26)),IF(AND(K26>=Ringkasan!$B$10,L26>=Ringkasan!$B$11),"yes",""),"") | Q26: gmgn; axiom; pumpfun-app | U26: 26
A27: a9Cct2wpjn4vWSR4rsytxm1URyk6vTXo4RTqXFpjyvD | C27: =COUNT(E27:G27) | D27: SolanaTracker | F27: 26 | I27: 4707.28 | K27: =IF(COUNT(H27:J27)>=2,MAX(H27:J27)-MIN(H27:J27),"") | L27: =IF(ISNUMBER(K27),IF(MAX(ABS(MAX(H27:J27)),ABS(MIN(H27:J27)))=0,"",K27/MAX(ABS(MAX(H27:J27)),ABS(MIN(H27:J27)))),"") | M27: =IF(AND(ISNUMBER(K27),ISNUMBER(L27)),IF(AND(K27>=Ringkasan!$B$10,L27>=Ringkasan!$B$11),"yes",""),"") | Q27: axiom | U27: 27
A28: ALiRQQjiJtfT44VcgLCur12oftvcSjnbUhZJJMPCxyi9 | C28: =COUNT(E28:G28) | D28: SolanaTracker | F28: 27 | I28: 4632.82 | K28: =IF(COUNT(H28:J28)>=2,MAX(H28:J28)-MIN(H28:J28),"") | L28: =IF(ISNUMBER(K28),IF(MAX(ABS(MAX(H28:J28)),ABS(MIN(H28:J28)))=0,"",K28/MAX(ABS(MAX(H28:J28)),ABS(MIN(H28:J28)))),"") | M28: =IF(AND(ISNUMBER(K28),ISNUMBER(L28)),IF(AND(K28>=Ringkasan!$B$10,L28>=Ringkasan!$B$11),"yes",""),"") | Q28: gmgn; axiom | U28: 28
A29: 4t6pyETLEd3o7Esm2zhqPVduti4fKXJWPtGWTYZtNLg6 | B29: 🖰 | C29: =COUNT(E29:G29) | D29: SolanaTracker | F29: 28 | I29: 4597.56 | K29: =IF(COUNT(H29:J29)>=2,MAX(H29:J29)-MIN(H29:J29),"") | L29: =IF(ISNUMBER(K29),IF(MAX(ABS(MAX(H29:J29)),ABS(MIN(H29:J29)))=0,"",K29/MAX(ABS(MAX(H29:J29)),ABS(MIN(H29:J29)))),"") | M29: =IF(AND(ISNUMBER(K29),ISNUMBER(L29)),IF(AND(K29>=Ringkasan!$B$10,L29>=Ringkasan!$B$11),"yes",""),"") | Q29: terminal; fomo | U29: 29
A30: 72qiszPvrwpXQesTUaiEeMEYtbXZ8Lqa2jkHuwSoR4Rs | B30: shrimproll | C30: =COUNT(E30:G30) | D30: SolanaTracker | F30: 29 | I30: 4588.24 | K30: =IF(COUNT(H30:J30)>=2,MAX(H30:J30)-MIN(H30:J30),"") | L30: =IF(ISNUMBER(K30),IF(MAX(ABS(MAX(H30:J30)),ABS(MIN(H30:J30)))=0,"",K30/MAX(ABS(MAX(H30:J30)),ABS(MIN(H30:J30)))),"") | M30: =IF(AND(ISNUMBER(K30),ISNUMBER(L30)),IF(AND(K30>=Ringkasan!$B$10,L30>=Ringkasan!$B$11),"yes",""),"") | Q30: fomo | U30: 30
A31: FT9cwJgg2vf6JcqvEe7A2SAxt469F7zBLtyhsqYW2YvH | B31: zixzah | C31: =COUNT(E31:G31) | D31: SolanaTracker | F31: 30 | I31: 4492.97 | K31: =IF(COUNT(H31:J31)>=2,MAX(H31:J31)-MIN(H31:J31),"") | L31: =IF(ISNUMBER(K31),IF(MAX(ABS(MAX(H31:J31)),ABS(MIN(H31:J31)))=0,"",K31/MAX(ABS(MAX(H31:J31)),ABS(MIN(H31:J31)))),"") | M31: =IF(AND(ISNUMBER(K31),ISNUMBER(L31)),IF(AND(K31>=Ringkasan!$B$10,L31>=Ringkasan!$B$11),"yes",""),"") | Q31: pumpfun-app | U31: 31
A32: AoQhsez9FxzbJuwhCDJiwCkDSYbvGv3khYAy8StH9R6V | B32: Soltranza | C32: =COUNT(E32:G32) | D32: SolanaTracker | F32: 31 | I32: 4369.4 | K32: =IF(COUNT(H32:J32)>=2,MAX(H32:J32)-MIN(H32:J32),"") | L32: =IF(ISNUMBER(K32),IF(MAX(ABS(MAX(H32:J32)),ABS(MIN(H32:J32)))=0,"",K32/MAX(ABS(MAX(H32:J32)),ABS(MIN(H32:J32)))),"") | M32: =IF(AND(ISNUMBER(K32),ISNUMBER(L32)),IF(AND(K32>=Ringkasan!$B$10,L32>=Ringkasan!$B$11),"yes",""),"") | Q32: pumpfun-app | U32: 32
A33: HaxVjQgLK9yjdMerZtwsEgPcJReEi42fEgQ33BihsDRc | C33: =COUNT(E33:G33) | D33: SolanaTracker | F33: 32 | I33: 4220.83 | K33: =IF(COUNT(H33:J33)>=2,MAX(H33:J33)-MIN(H33:J33),"") | L33: =IF(ISNUMBER(K33),IF(MAX(ABS(MAX(H33:J33)),ABS(MIN(H33:J33)))=0,"",K33/MAX(ABS(MAX(H33:J33)),ABS(MIN(H33:J33)))),"") | M33: =IF(AND(ISNUMBER(K33),ISNUMBER(L33)),IF(AND(K33>=Ringkasan!$B$10,L33>=Ringkasan!$B$11),"yes",""),"") | Q33: terminal; axiom | U33: 33
A34: BGb7SiB1hw9bAbUarByVksALdXaz5iaD8mCKQRZJvK7T | C34: =COUNT(E34:G34) | D34: SolanaTracker | F34: 33 | I34: 4176.39 | K34: =IF(COUNT(H34:J34)>=2,MAX(H34:J34)-MIN(H34:J34),"") | L34: =IF(ISNUMBER(K34),IF(MAX(ABS(MAX(H34:J34)),ABS(MIN(H34:J34)))=0,"",K34/MAX(ABS(MAX(H34:J34)),ABS(MIN(H34:J34)))),"") | M34: =IF(AND(ISNUMBER(K34),ISNUMBER(L34)),IF(AND(K34>=Ringkasan!$B$10,L34>=Ringkasan!$B$11),"yes",""),"") | Q34: terminal; axiom | U34: 34
A35: MRLJSy9LVb6Qy53ae1jXrsKEQW2vS7J4uSsUHBxes5N | C35: =COUNT(E35:G35) | D35: SolanaTracker | F35: 34 | I35: 4154.42 | K35: =IF(COUNT(H35:J35)>=2,MAX(H35:J35)-MIN(H35:J35),"") | L35: =IF(ISNUMBER(K35),IF(MAX(ABS(MAX(H35:J35)),ABS(MIN(H35:J35)))=0,"",K35/MAX(ABS(MAX(H35:J35)),ABS(MIN(H35:J35)))),"") | M35: =IF(AND(ISNUMBER(K35),ISNUMBER(L35)),IF(AND(K35>=Ringkasan!$B$10,L35>=Ringkasan!$B$11),"yes",""),"") | Q35: terminal; axiom | U35: 35
A36: 9cAz6WUKH4UNqzv6uT7TWitp8QHExBoFt3cTqrPBLGFq | C36: =COUNT(E36:G36) | D36: SolanaTracker | F36: 35 | I36: 4040.3 | K36: =IF(COUNT(H36:J36)>=2,MAX(H36:J36)-MIN(H36:J36),"") | L36: =IF(ISNUMBER(K36),IF(MAX(ABS(MAX(H36:J36)),ABS(MIN(H36:J36)))=0,"",K36/MAX(ABS(MAX(H36:J36)),ABS(MIN(H36:J36)))),"") | M36: =IF(AND(ISNUMBER(K36),ISNUMBER(L36)),IF(AND(K36>=Ringkasan!$B$10,L36>=Ringkasan!$B$11),"yes",""),"") | Q36: axiom | U36: 36
A37: BnNMkMRhQmAd56KPN9141ULX9HhPmQrkSzYxr8CCPbyX | B37: flatkraken21075 | C37: =COUNT(E37:G37) | D37: SolanaTracker | F37: 36 | I37: 4033.66 | K37: =IF(COUNT(H37:J37)>=2,MAX(H37:J37)-MIN(H37:J37),"") | L37: =IF(ISNUMBER(K37),IF(MAX(ABS(MAX(H37:J37)),ABS(MIN(H37:J37)))=0,"",K37/MAX(ABS(MAX(H37:J37)),ABS(MIN(H37:J37)))),"") | M37: =IF(AND(ISNUMBER(K37),ISNUMBER(L37)),IF(AND(K37>=Ringkasan!$B$10,L37>=Ringkasan!$B$11),"yes",""),"") | Q37: axiom; pumpfun-app | U37: 37
A38: Bp95jUJaBUc4ZQ2c5c2V6YMf1FEDDUMKRCXdkYBvoTXx | C38: =COUNT(E38:G38) | D38: SolanaTracker | F38: 37 | I38: 3977.37 | K38: =IF(COUNT(H38:J38)>=2,MAX(H38:J38)-MIN(H38:J38),"") | L38: =IF(ISNUMBER(K38),IF(MAX(ABS(MAX(H38:J38)),ABS(MIN(H38:J38)))=0,"",K38/MAX(ABS(MAX(H38:J38)),ABS(MIN(H38:J38)))),"") | M38: =IF(AND(ISNUMBER(K38),ISNUMBER(L38)),IF(AND(K38>=Ringkasan!$B$10,L38>=Ringkasan!$B$11),"yes",""),"") | Q38: gmgn; axiom | U38: 38
A39: fagtUj7V7wKxSo2Jjc1NfcBexwnygGYbTYgN9eNXx8X | C39: =COUNT(E39:G39) | D39: SolanaTracker | F39: 38 | I39: 3942.66 | K39: =IF(COUNT(H39:J39)>=2,MAX(H39:J39)-MIN(H39:J39),"") | L39: =IF(ISNUMBER(K39),IF(MAX(ABS(MAX(H39:J39)),ABS(MIN(H39:J39)))=0,"",K39/MAX(ABS(MAX(H39:J39)),ABS(MIN(H39:J39)))),"") | M39: =IF(AND(ISNUMBER(K39),ISNUMBER(L39)),IF(AND(K39>=Ringkasan!$B$10,L39>=Ringkasan!$B$11),"yes",""),"") | Q39: terminal; axiom | U39: 39
A40: BUkTdidtehRJ6YvKDErxcFaoEGTVTEtKHedePgE6Pq4z | C40: =COUNT(E40:G40) | D40: SolanaTracker | F40: 39 | I40: 3888.33 | K40: =IF(COUNT(H40:J40)>=2,MAX(H40:J40)-MIN(H40:J40),"") | L40: =IF(ISNUMBER(K40),IF(MAX(ABS(MAX(H40:J40)),ABS(MIN(H40:J40)))=0,"",K40/MAX(ABS(MAX(H40:J40)),ABS(MIN(H40:J40)))),"") | M40: =IF(AND(ISNUMBER(K40),ISNUMBER(L40)),IF(AND(K40>=Ringkasan!$B$10,L40>=Ringkasan!$B$11),"yes",""),"") | Q40: gmgn; axiom | U40: 40
...

Sheet Vybe
A1: Tidak ada data dari Vybe.
A2: Status: gagal
A3: Error: Vybe returned no traders for this token.

Sheet SolanaTracker
A1: rank | B1: wallet | C1: labels | D1: identity_name | E1: realized_pnl_usd | F1: unrealized_pnl_usd | G1: total_pnl_usd | H1: roi | I1: invested_usd | J1: proceeds_usd | K1: buys | L1: sells | M1: first_trade_utc | N1: last_trade_utc | O1: hold_time_secs | P1: balance | Q1: value_usd | R1: wallet_lifetime_realized_pnl_usd | S1: wallet_lifetime_trades | T1: wallet_tokens_traded
A2: 1 | B2: 3jvB7JMR7QhTqohucrQqiB6UPazbB8e2Zo6mQSKDCCGq | C2: gmgn;axiom;pumpfun-app;bloom | D2: SandySulkyFruit | E2: 20801.32 | F2: 0 | G2: 20801.32 | H2: 269.88 | I2: 7707.64 | J2: 28508.96 | K2: 10 | L2: 24 | M2: 2026-09-17T19:15:49Z | N2: 2026-09-26T04:36:55Z | O2: 724866 | P2: 0 | Q2: 0 | R2: 230839.18 | S2: 2114 | T2: 470
A3: 2 | B3: AYZryL5JYFhAJ7PtA9uvebDqcFrifcPTucvDyjbd7xzN | C3: terminal;axiom | E3: 18694.13 | F3: 0 | G3: 18694.13 | H3: 1707.63 | I3: 1094.74 | J3: 19788.87 | K3: 3 | L3: 44 | M3: 2026-09-17T19:14:52Z | N3: 2026-09-17T19:27:20Z | O3: 749 | P3: 0 | Q3: 0 | R3: 217779.29 | S3: 10981 | T3: 2679
A4: 3 | B4: 4CwrH924ZreiA4rjEfWRbVa28LrzYb18EBjGhLLZwBjX | C4: potential_bot;fomo | D4: Spoily | E4: 18640.15 | F4: 0 | G4: 18640.15 | H4: 503.94 | I4: 3698.9 | J4: 22339.05 | K4: 8 | L4: 14 | M4: 2026-09-17T19:14:20Z | N4: 2026-09-26T04:28:57Z | O4: 724477 | P4: 0 | Q4: 0 | R4: 88417.99 | S4: 2475 | T4: 674
A5: 4 | B5: 8Hh4H35D498baNnWXdsAct6pj5LtnkNS1Xi8KtQq6huK | C5: fomo | D5: Saif | E5: 15226.57 | F5: 0 | G5: 15226.57 | H5: 298.56 | I5: 5100 | J5: 20326.57 | K5: 5 | L5: 14 | M5: 2026-09-17T19:16:03Z | N5: 2026-09-26T15:56:16Z | O5: 765614 | P5: 0 | Q5: 0 | R5: 34836.66 | S5: 1670 | T5: 480
A6: 5 | B6: EJFEveW2fy9o7ARLpU7ch7aHbPwK3hLKGTmQ9EkNZa43 | C6: fomo | D6: FirmDeafFox | E6: 14197.44 | F6: 0 | G6: 14197.44 | H6: 1130.15 | I6: 1256.25 | J6: 15453.68 | K6: 2 | L6: 5 | M6: 2026-09-24T14:07:54Z | N6: 2026-09-26T04:23:45Z | O6: 137751 | P6: 0 | Q6: 0 | R6: 8077.47 | S6: 589 | T6: 76
A7: 6 | B7: 4nQ4VWTAadJB2sgQqabBVBft3VPpQcHi3RdX2qcJZTMD | C7: axiom | E7: 11818.44 | F7: 0 | G7: 11818.44 | H7: 1469.67 | I7: 804.15 | J7: 12622.6 | K7: 8 | L7: 32 | M7: 2026-09-17T19:12:39Z | N7: 2026-09-17T22:40:02Z | O7: 2376080 | P7: 5.587935e-09 | Q7: 0 | R7: -21131.84 | S7: 3793 | T7: 913
A8: 7 | B8: 3ULrdcEaBHsXACWnMo6foav1nkV7QDsPipsUyY2fT5AS | C8: potential_bot;pumpfun-app | D8: newlobster60567 | E8: 11324.02 | F8: 0 | G8: 11324.02 | H8: 218.41 | I8: 5184.73 | J8: 16508.75 | K8: 39 | L8: 47 | M8: 2026-09-17T21:20:30Z | N8: 2026-09-22T02:14:12Z | O8: 363222 | P8: 0 | Q8: 0 | R8: 811646.17 | S8: 3126 | T8: 173
A9: 8 | B9: CyaE1VxvBrahnPWkqm5VsdCvyS2QmNht2UFrKJHga54o | C9: kol;terminal;axiom;photon;pumpfun-app;bloom;sns | D9: Cented | E9: 10423.99 | F9: 0 | G9: 10423.99 | H9: 252.65 | I9: 4125.82 | J9: 14549.81 | K9: 10 | L9: 20 | M9: 2026-09-17T19:15:44Z | N9: 2026-09-17T19:43:42Z | O9: 2375894 | P9: 5.122274e-09 | Q9: 0 | R9: 14378891 | S9: 552547 | T9: 107759
A10: 9 | B10: 5B79fMkcFeRTiwm7ehsZsFiKsC7m7n1Bgv9yLxPp9q2X | C10: kol;axiom;sns | D10: bandit | E10: 10400.93 | F10: 0 | G10: 10400.93 | H10: 1970.84 | I10: 527.74 | J10: 10928.67 | K10: 4 | L10: 8 | M10: 2026-09-17T19:12:08Z | N10: 2026-09-17T19:36:15Z | O10: 1447 | P10: 0 | Q10: 0 | R10: 1512535.9 | S10: 163123 | T10: 29972
A11: 10 | B11: EYkRnmNfmSFUkzz4vYE2uii2UW2cTSr2Urf32BUkUX9k | E11: 9666.4 | F11: 0 | G11: 9666.4 | H11: 0 | I11: 0 | J11: 9666.4 | K11: 0 | L11: 16 | M11: 2026-09-26T03:45:34Z | N11: 2026-09-26T04:21:36Z | P11: 0 | Q11: 0 | R11: 9666.4 | S11: 16 | T11: 1
A12: 11 | B12: 3nLh14fRyZr1EBpp7jJqwBqKt8uLBFZ1rTmVTfLvnkfj | C12: potential_bot;axiom | E12: 9051.79 | F12: 0 | G12: 9051.79 | H12: 513.63 | I12: 1762.33 | J12: 10814.13 | K12: 6 | L12: 19 | M12: 2026-09-17T19:18:26Z | N12: 2026-09-24T23:09:28Z | O12: 618662 | P12: 0 | Q12: 0 | R12: 497256.03 | S12: 14370 | T12: 2255
A13: 12 | B13: 5tNXmLdWCY58mjGVn6a6hTxLqyDntKAetwWcLaphRnL | C13: axiom | E13: 8497.26 | F13: 0 | G13: 8497.26 | H13: 723.09 | I13: 1175.14 | J13: 9672.39 | K13: 2 | L13: 8 | M13: 2026-09-24T23:18:53Z | N13: 2026-09-26T04:27:27Z | O13: 1756505 | P13: 2.32831e-10 | Q13: 0 | R13: 6921.87 | S13: 49 | T13: 8
A14: 13 | B14: WJWQRpigXNgnMH8wdjLuo5XfuY3sk6WHc3DAaBXf8Vx | C14: axiom | E14: 7679.67 | F14: 0 | G14: 7679.67 | H14: 874.61 | I14: 878.07 | J14: 8557.75 | K14: 6 | L14: 3 | M14: 2026-09-17T19:19:31Z | N14: 2026-09-18T01:00:12Z | O14: 20441 | P14: 0 | Q14: 0 | R14: 1364.61 | S14: 2038 | T14: 589
A15: 14 | B15: 922M9fBTzwGfC4Gqu3WxB8S89WHaTfVAUZKwK5PNtZpk | C15: potential_bot | E15: 7145.46 | F15: 0 | G15: 7145.46 | H15: 5.17 | I15: 138203.95 | J15: 145345 | K15: 260 | L15: 2598 | M15: 2026-09-17T19:25:36Z | N15: 2026-09-26T12:38:36Z | O15: 753181 | P15: 0 | Q15: 0 | R15: 1134227.4 | S15: 598129 | T15: 2830
A16: 15 | B16: HyGWBXCTcSW3F9dPdZhz5RD4ubjKyjmMccArDSEBfYxM | C16: terminal;axiom | E16: 6992.96 | F16: 0 | G16: 6992.96 | H16: 274.27 | I16: 2549.65 | J16: 9542.62 | K16: 3 | L16: 11 | M16: 2026-09-17T19:21:37Z | N16: 2026-09-17T19:36:34Z | O16: 2375542 | P16: 4.07454e-10 | Q16: 0 | R16: 38895.84 | S16: 1302 | T16: 348
A17: 16 | B17: 5pHeNsWMVEi1cbMzLhgqABnhEUwRTSzy5vBfeGWyJfxS | C17: potential_bot;fomo | D17: ‎ ‎ ‎ | E17: 6435.1 | F17: 0 | G17: 6435.1 | H17: 31.37 | I17: 20512.8 | J17: 26947.9 | K17: 23 | L17: 18 | M17: 2026-09-17T19:25:49Z | N17: 2026-09-27T17:57:06Z | O17: 858677 | P17: 0 | Q17: 0 | R17: -42618.23 | S17: 2232 | T17: 144
A18: 17 | B18: 6dC4Rvt1c6mv6M27QeAxRCCbXjUaZPFRZPxZn2rLXN7s | C18: potential_bot;gmgn;axiom | E18: 6405.29 | F18: 0 | G18: 6405.29 | H18: 490.9 | I18: 1304.8 | J18: 7710.09 | K18: 10 | L18: 82 | M18: 2026-09-17T19:15:02Z | N18: 2026-09-17T19:35:21Z | O18: 1219 | P18: 0 | Q18: 0 | R18: 78093.31 | S18: 4902 | T18: 1124
A19: 18 | B19: 1CNg1DM3egT1qiHNFNFNAFsCmgpczHHJk2fZdnkJyUv | C19: potential_bot;terminal;axiom | E19: 6014.38 | F19: 0 | G19: 6014.38 | H19: 0 | I19: 0 | J19: 6014.38 | K19: 0 | L19: 2 | M19: 2026-09-28T22:55:31Z | N19: 2026-09-28T22:55:32Z | P19: 0 | Q19: 0 | R19: 64334.79 | S19: 497 | T19: 182
A20: 19 | B20: 8HH3M6SfUCC9yGM3ytaFQWnDc19tSBYCNJBnqeWaQ8Xb | C20: pumpfun-app | D20: fomo_sexual | E20: 5839.45 | F20: 0 | G20: 5839.45 | H20: 91.67 | I20: 6370.11 | J20: 12209.56 | K20: 4 | L20: 2 | M20: 2026-09-17T19:19:21Z | N20: 2026-09-17T21:58:10Z | O20: 9529 | P20: 0 | Q20: 0 | R20: 462993.45 | S20: 2606 | T20: 567
A21: 20 | B21: 3EmnFHt5dFo5RW4oJf4zruBKJtm2gNgTkGCB5n6dXDvf | C21: fomo | E21: 5696.76 | F21: 0 | G21: 5696.76 | H21: 131.84 | I21: 4321 | J21: 10017.76 | K21: 3 | L21: 4 | M21: 2026-09-17T19:23:07Z | N21: 2026-09-17T21:25:18Z | O21: 7331 | P21: 0 | Q21: 0 | R21: 15024.59 | S21: 673 | T21: 220
A22: 21 | B22: gasBidSWW5zmwXs3gn8TG2ijzKkrwpyM7ucwjgDQst6 | C22: potential_bot | E22: 5684.03 | F22: 0 | G22: 5684.03 | H22: 267.46 | I22: 2125.18 | J22: 7809.2 | K22: 64 | L22: 89 | M22: 2026-09-17T21:15:35Z | N22: 2026-09-26T04:04:59Z | O22: 715763 | P22: 0 | Q22: 0 | R22: 7942952.5 | S22: 186047 | T22: 2291
A23: 22 | B23: 2tiFfUNd4HEYg5XtSiNgrfptZ5LSjNU4dCFbg5YqWbBz | C23: gmgn;axiom | E23: 5145.71 | F23: 0 | G23: 5145.71 | H23: 740.96 | I23: 694.46 | J23: 5840.17 | K23: 4 | L23: 20 | M23: 2026-09-17T19:17:12Z | N23: 2026-09-17T19:23:19Z | O23: 367 | P23: 0 | Q23: 0 | R23: 41704.44 | S23: 9517 | T23: 779
A24: 23 | B24: nMK9myLJSftWpbacFUnaHx5bG3VUmbucghQMyHMgFZU | C24: axiom | E24: 5109.42 | F24: 0 | G24: 5109.42 | H24: 289.85 | I24: 1762.81 | J24: 6872.22 | K24: 3 | L24: 5 | M24: 2026-09-24T23:19:48Z | N24: 2026-09-26T03:16:08Z | O24: 100580 | P24: 0 | Q24: 0 | R24: -2755.72 | S24: 259 | T24: 34
A25: 24 | B25: 4xd3Y2qvX43wwfLupdQVsE5ZTpnhXmpn8Dmf4Hufkj9n | C25: axiom | E25: 4729 | F25: 0 | G25: 4729 | H25: 24.98 | I25: 18929.66 | J25: 23658.66 | K25: 47 | L25: 34 | M25: 2026-09-17T19:25:44Z | N25: 2026-09-17T20:01:01Z | O25: 2375294 | P25: 8.847564e-09 | Q25: 0 | R25: 471800.61 | S25: 38811 | T25: 7690
A26: 25 | B26: DXYo85dMRjN72mEwwMADfPcsSknup9D7aoH9TExCDpns | C26: gmgn;axiom;pumpfun-app | D26: robustorca18145 | E26: 4724.37 | F26: 0 | G26: 4724.37 | H26: 392.06 | I26: 1205.02 | J26: 5929.4 | K26: 9 | L26: 56 | M26: 2026-09-17T19:15:02Z | N26: 2026-09-17T19:35:32Z | O26: 1231 | P26: 0 | Q26: 0 | R26: 213533.38 | S26: 10578 | T26: 1973
A27: 26 | B27: a9Cct2wpjn4vWSR4rsytxm1URyk6vTXo4RTqXFpjyvD | C27: axiom | E27: 4707.28 | F27: 0 | G27: 4707.28 | H27: 795.98 | I27: 591.38 | J27: 5298.67 | K27: 6 | L27: 26 | M27: 2026-09-17T19:15:02Z | N27: 2026-09-17T19:44:37Z | O27: 2375936 | P27: 1.164153e-09 | Q27: 0 | R27: 267973.09 | S27: 220155 | T27: 28296
A28: 27 | B28: ALiRQQjiJtfT44VcgLCur12oftvcSjnbUhZJJMPCxyi9 | C28: gmgn;axiom | E28: 4632.82 | F28: 0 | G28: 4632.82 | H28: 785.07 | I28: 590.11 | J28: 5222.93 | K28: 4 | L28: 19 | M28: 2026-09-17T19:17:12Z | N28: 2026-09-17T19:23:12Z | O28: 361 | P28: 0 | Q28: 0 | R28: 33267.11 | S28: 7585 | T28: 730
A29: 28 | B29: 4t6pyETLEd3o7Esm2zhqPVduti4fKXJWPtGWTYZtNLg6 | C29: terminal;fomo | D29: 🖰 | E29: 4597.56 | F29: 0 | G29: 4597.56 | H29: 171.81 | I29: 2676.01 | J29: 7273.57 | K29: 7 | L29: 5 | M29: 2026-09-17T19:22:57Z | N29: 2026-09-17T21:00:26Z | O29: 5849 | P29: 0 | Q29: 0 | R29: 4799.06 | S29: 535 | T29: 125
A30: 29 | B30: 72qiszPvrwpXQesTUaiEeMEYtbXZ8Lqa2jkHuwSoR4Rs | C30: fomo | D30: shrimproll | E30: 4588.24 | F30: 0 | G30: 4588.24 | H30: 30.21 | I30: 15187.53 | J30: 19775.77 | K30: 5 | L30: 20 | M30: 2026-09-17T19:24:00Z | N30: 2026-09-26T04:22:46Z | O30: 723526 | P30: 0 | Q30: 0 | R30: 8892.45 | S30: 194 | T30: 59
A31: 30 | B31: FT9cwJgg2vf6JcqvEe7A2SAxt469F7zBLtyhsqYW2YvH | C31: pumpfun-app | D31: zixzah | E31: 4492.97 | F31: 0 | G31: 4492.97 | H31: 184.92 | I31: 2429.69 | J31: 6922.66 | K31: 4 | L31: 20 | M31: 2026-09-17T19:18:30Z | N31: 2026-09-18T22:22:23Z | O31: 97434 | P31: 0 | Q31: 0 | R31: -53912.25 | S31: 1291 | T31: 480
A32: 31 | B32: AoQhsez9FxzbJuwhCDJiwCkDSYbvGv3khYAy8StH9R6V | C32: pumpfun-app | D32: Soltranza | E32: 4369.4 | F32: 0 | G32: 4369.4 | H32: 32.52 | I32: 13434.18 | J32: 17803.58 | K32: 121 | L32: 96 | M32: 2026-09-19T14:42:19Z | N32: 2026-10-13T15:38:23Z | O32: 2076965 | P32: 0 | Q32: 0 | R32: 161907.32 | S32: 9765 | T32: 183
A33: 32 | B33: HaxVjQgLK9yjdMerZtwsEgPcJReEi42fEgQ33BihsDRc | C33: terminal;axiom | E33: 4220.83 | F33: 0 | G33: 4220.83 | H33: 563.26 | I33: 749.36 | J33: 4970.19 | K33: 14 | L33: 66 | M33: 2026-09-17T19:17:21Z | N33: 2026-09-17T19:28:49Z | O33: 688 | P33: 0 | Q33: 0 | R33: 10867.43 | S33: 2495 | T33: 429
A34: 33 | B34: BGb7SiB1hw9bAbUarByVksALdXaz5iaD8mCKQRZJvK7T | C34: terminal;axiom | E34: 4176.39 | F34: 0 | G34: 4176.39 | H34: 543.98 | I34: 767.74 | J34: 4944.13 | K34: 14 | L34: 66 | M34: 2026-09-17T19:17:21Z | N34: 2026-09-17T19:28:49Z | O34: 688 | P34: 0 | Q34: 0 | R34: 2455.62 | S34: 1625 | T34: 332
A35: 34 | B35: MRLJSy9LVb6Qy53ae1jXrsKEQW2vS7J4uSsUHBxes5N | C35: terminal;axiom | E35: 4154.42 | F35: 0 | G35: 4154.42 | H35: 576.89 | I35: 720.14 | J35: 4874.56 | K35: 14 | L35: 66 | M35: 2026-09-17T19:17:21Z | N35: 2026-09-17T19:28:49Z | O35: 688 | P35: 0 | Q35: 0 | R35: 5385.29 | S35: 2596 | T35: 423
A36: 35 | B36: 9cAz6WUKH4UNqzv6uT7TWitp8QHExBoFt3cTqrPBLGFq | C36: axiom | E36: 4040.3 | F36: 0 | G36: 4040.3 | H36: 5125.89 | I36: 78.82 | J36: 4119.12 | K36: 2 | L36: 5 | M36: 2026-09-17T19:14:32Z | N36: 2026-09-17T19:43:35Z | O36: 1742 | P36: 0 | Q36: 0 | R36: 10921.44 | S36: 678 | T36: 235
A37: 36 | B37: BnNMkMRhQmAd56KPN9141ULX9HhPmQrkSzYxr8CCPbyX | C37: axiom;pumpfun-app | D37: flatkraken21075 | E37: 4033.66 | F37: 0 | G37: 4033.66 | H37: 280.83 | I37: 1436.32 | J37: 5469.97 | K37: 8 | L37: 14 | M37: 2026-09-17T19:15:05Z | N37: 2026-09-18T17:08:08Z | O37: 78783 | P37: 0 | Q37: 0 | R37: 116526.73 | S37: 23820 | T37: 5154
A38: 37 | B38: Bp95jUJaBUc4ZQ2c5c2V6YMf1FEDDUMKRCXdkYBvoTXx | C38: gmgn;axiom | E38: 3977.37 | F38: 0 | G38: 3977.37 | H38: 706.72 | I38: 562.79 | J38: 4540.17 | K38: 4 | L38: 16 | M38: 2026-09-17T19:17:12Z | N38: 2026-09-17T19:24:00Z | O38: 408 | P38: 0 | Q38: 0 | R38: 40107.96 | S38: 6631 | T38: 681
A39: 38 | B39: fagtUj7V7wKxSo2Jjc1NfcBexwnygGYbTYgN9eNXx8X | C39: terminal;axiom | E39: 3942.66 | F39: 0 | G39: 3942.66 | H39: 548.55 | I39: 718.75 | J39: 4661.41 | K39: 14 | L39: 66 | M39: 2026-09-17T19:17:21Z | N39: 2026-09-17T19:28:49Z | O39: 688 | P39: 0 | Q39: 0 | R39: 6712.5 | S39: 2682 | T39: 429
A40: 39 | B40: BUkTdidtehRJ6YvKDErxcFaoEGTVTEtKHedePgE6Pq4z | C40: gmgn;axiom | E40: 3888.33 | F40: 0 | G40: 3888.33 | H40: 613.18 | I40: 634.12 | J40: 4522.45 | K40: 4 | L40: 16 | M40: 2026-09-17T19:17:12Z | N40: 2026-09-17T19:23:26Z | O40: 374 | P40: 0 | Q40: 0 | R40: 38621.3 | S40: 6638 | T40: 678
...

Sheet GMGN
A1: Tidak ada data dari GMGN.
A2: Status: gagal
A3: Error: GMGN API error (HTTP 401): code=401 AUTH_TIMESTAMP_EXPIRED timestamp expired Check GMGN_API_KEY (the API key, not the private key). GMGN only works over IPv4, so disable IPv6 if the key is correct, and make sure this PC's clock is accurate (the server allows about 5 seconds of drift).

Sheet Log
A1: Log run
A3: Lingkungan dan parameter
A4: Suite | B4: 1.0.0
A5: Python | B5: 3.14.6
A6: Sistem operasi | B6: Windows-11-10.0.22000-SP0
A7: openpyxl | B7: 3.1.5
A8: Mint | B8: 9U1f18idDeySFnYrurxqT1f5n5nE4g4Uk5LLzP69bh1
A9: Snapshot (UTC) | B9: 2026-10-15 07:14:27
A10: Batas waktu per sumber (detik) | B10: 120
A11: Arsip raw JSON diminta | B11: ya
A12: Ambang awal selisih (USD / relatif) | B12: 10 / 25%
A14: Proses per sumber (kunci API tidak pernah dicatat; setiap proses hanya menerima kuncinya sendiri)
A15: Sumber | B15: Status | C15: Kode keluar | D15: Perintah | E15: Folder kerja | F15: Mulai (UTC) | G15: Selesai (UTC) | H15: Durasi (dtk) | I15: Berkas | J15: Catatan
A16: Vybe | B16: gagal | C16: 1 | D16: C:\Python314\python.exe "D:\V 1.1 - backup\V1.2\top-trader-suite\vybe\main.py" 9U1f18idDeySFnYrurxqT1f5n5nE4g4Uk5LLzP69bh1 | E16: D:\V 1.1 - backup\V1.2\top-trader-suite\output\_raw\9U1f18id_20261015_071427\vybe | F16: 2026-10-15 07:14:27 | G16: 2026-10-15 07:14:29 | H16: 2.1 | J16: Error: Vybe returned no traders for this token.
A17: SolanaTracker | B17: ok | C17: 0 | D17: C:\Python314\python.exe "D:\V 1.1 - backup\V1.2\top-trader-suite\solanatracker\main.py" 9U1f18idDeySFnYrurxqT1f5n5nE4g4Uk5LLzP69bh1 --raw | E17: D:\V 1.1 - backup\V1.2\top-trader-suite\output\_raw\9U1f18id_20261015_071427\solanatracker | F17: 2026-10-15 07:14:27 | G17: 2026-10-15 07:14:30 | H17: 2.6 | I17: solanatracker_top_traders_9U1f18idDeySFnYrurxqT1f5n5nE4g4Uk5LLzP69bh1_20261015_071430.csv, solanatracker_top_traders_9U1f18idDeySFnYrurxqT1f5n5nE4g4Uk5LLzP69bh1_20261015_071430.raw.json
A18: GMGN | B18: gagal | C18: 1 | D18: C:\Python314\python.exe "D:\V 1.1 - backup\V1.2\top-trader-suite\gmgn\main.py" 9U1f18idDeySFnYrurxqT1f5n5nE4g4Uk5LLzP69bh1 --raw | E18: D:\V 1.1 - backup\V1.2\top-trader-suite\output\_raw\9U1f18id_20261015_071427\gmgn | F18: 2026-10-15 07:14:27 | G18: 2026-10-15 07:14:29 | H18: 2 | J18: Error: GMGN API error (HTTP 401): code=401 AUTH_TIMESTAMP_EXPIRED timestamp expired Check GMGN_API_KEY (the API key, not the private key). GMGN only works over IPv4, so disable IPv6 if the key is correct, and make sure this PC's clock is accurate (the server allows about 5 seconds of drift).
A20: Keluaran proses (dipotong bila panjang)
A21: Vybe stderr | B21: Error: Vybe returned no traders for this token.
A22: SolanaTracker stdout | B22: Created output\solanatracker_top_traders_9U1f18idDeySFnYrurxqT1f5n5nE4g4Uk5LLzP69bh1_20261015_071430.csv (100 traders) - SOLCAT (Solana Cat)
A23: GMGN stderr | B23: Error: GMGN API error (HTTP 401): code=401 AUTH_TIMESTAMP_EXPIRED timestamp expired Check GMGN_API_KEY (the API key, not the private key). GMGN only works over IPv4, so disable IPv6 if the key is correct, and make sure this PC's clock is accurate (the server allows about 5 seconds of drift).
A25: Sidik jari kode (SHA-256, 16 karakter pertama) - untuk memastikan versi kode yang dijalankan
A26: Sumber | B26: Berkas | C26: SHA-256
A27: Vybe | B27: main.py | C27: 249919e2e3f83dbb
A28: Vybe | B28: vybe.py | C28: f88ad250cbb9186d
A29: Vybe | B29: csv_writer.py | C29: 56cd7548f0763d3f
A30: SolanaTracker | B30: main.py | C30: 87e2df6587fb4f35
A31: SolanaTracker | B31: solanatracker.py | C31: 24dc000755d40d1b
A32: SolanaTracker | B32: csv_writer.py | C32: 95665c59391c53c0
A33: GMGN | B33: main.py | C33: 1e1e9abfe03032c3
A34: GMGN | B34: gmgn.py | C34: 9372cc27b33b6186
A35: GMGN | B35: csv_writer.py | C35: c23305386940d1ab
