Workbook

Sheet Ringkasan
A1: Ringkasan run - audit lintas sumber
A3: Mint | B3: CoHH4XfCpEcAuQga8iSr3hCta3vyFxYW6BtQRAV3xQMo
A4: Waktu snapshot (UTC) | B4: 2026-10-15 06:26:26
A5: Sumber diminta | B5: Vybe, SolanaTracker, GMGN
A6: Sumber berhasil | B6: 2 dari 3 (Vybe, SolanaTracker)
A7: Versi suite / Python | B7: 1.0.0 / 3.14.6
A9: Parameter (sel kuning boleh diubah; kolom flag_spread di sheet Gabungan dan hitungannya di sini ikut dihitung ulang)
A10: Ambang selisih realized (USD) >= | B10: 10
A11: Ambang selisih relatif >= | B11: 0.25
A12: Nilai awal berasal dari argumen --spread-usd dan --spread-pct. Selisih relatif = (tertinggi - terendah) / nilai absolut terbesar.
A14: Status per sumber
A15: Sumber | B15: Status | C15: Baris | D15: Mulai (UTC) | E15: Selesai (UTC) | F15: Durasi (dtk) | G15: Aktivitas terbaru di daftar (UTC) | H15: Selisih ke waktu selesai (menit) | I15: Aktivitas tertua di daftar (UTC) | J15: Catatan
A16: Vybe | B16: ok | C16: 100 | D16: 2026-10-15 06:26:26 | E16: 2026-10-15 06:26:32 | F16: 6 | G16: n/a (CSV tanpa kolom waktu)
A17: SolanaTracker | B17: ok | C17: 100 | D17: 2026-10-15 06:26:26 | E17: 2026-10-15 06:26:32 | F17: 6.1 | G17: 2026-10-15 06:25:35 | H17: 1 | I17: 2026-10-15 04:58:28
A18: GMGN | B18: gagal | D18: 2026-10-15 06:26:26 | E18: 2026-10-15 06:26:29 | F18: 3.4 | J18: Error: GMGN API error (HTTP 401): code=401 AUTH_TIMESTAMP_EXPIRED timestamp expired Check GMGN_API_KEY (the API key, not the private key). GMGN only works over IPv4, so disable IPv6 if the key is correct, and make sure this PC's clock is accurate (the server allows about 5 seconds of drift).
A19: 'Aktivitas terbaru/tertua' hanya dari wallet yang ada di daftar (bukan seluruh token), jadi menunjukkan perkiraan kasar keterlambatan data.
A20: Aktivitas tertua yang terlihat: 2026-10-15 04:58:28 UTC (sekitar 1.47 jam sebelum snapshot).
A22: Cakupan wallet (rumus Excel atas sheet Gabungan)
A23: Wallet unik (gabungan) | B23: =COUNTA(Gabungan!$A$2:$A$193)
A24: Ada di semua 2 sumber | B24: =COUNTIF(Gabungan!$C$2:$C$193,2)
A25: Hanya di 1 sumber | B25: =COUNTIF(Gabungan!$C$2:$C$193,1)
A26: hanya di Vybe | B26: =COUNTIF(Gabungan!$N$2:$N$193,"Vybe")
A27: hanya di SolanaTracker | B27: =COUNTIF(Gabungan!$N$2:$N$193,"SolanaTracker")
A28: Ada di Vybe dan SolanaTracker | B28: =COUNTIFS(Gabungan!$E$2:$E$193,">0",Gabungan!$F$2:$F$193,">0")
A29: Wallet dengan selisih realized besar (flag_spread) | B29: =COUNTIF(Gabungan!$M$2:$M$193,"yes")
A30: Wallet dengan perbedaan peran (role_disagreement) | B30: =SUMPRODUCT(--(LEN(Gabungan!$O$2:$O$193)>0))
A32: Kecocokan realized PnL untuk wallet yang sama (dihitung oleh skrip Python, bukan rumus Excel)
A33: Pasangan | B33: Wallet bersama | C33: Median selisih (USD) | D33: Median selisih relatif | E33: Korelasi peringkat (Spearman) | F33: Overlap top-10
A34: Vybe vs SolanaTracker | B34: 8 | C34: 1.3572266 | D34: 0.0015561146 | E34: 0.92857143 | F34: 1/10
A36: Catatan
A37: Yang dibandingkan hanya realized PnL. Unrealized bergantung pada harga yang dipakai tiap provider saat menghitung, jadi hanya indikatif dan tidak dinilai selisihnya.
A38: Vybe mengembalikan 100 baris (batas 100). Wallet di luar daftar tidak terlihat, jadi 'hanya di satu sumber' bisa disebabkan daftar yang terpotong.
A39: SolanaTracker mengembalikan 100 baris (batas 100). Wallet di luar daftar tidak terlihat, jadi 'hanya di satu sumber' bisa disebabkan daftar yang terpotong.
A41: Kamus kolom sheet Gabungan
A42: rank_*: peringkat wallet di CSV provider itu (urutan realized PnL); kosong = wallet tidak ada di daftar provider itu.
A43: realized_*: realized_pnl_usd apa adanya dari provider; tidak ada rata-rata dan tidak ada penyatuan definisi.
A44: n_sources, spread_usd, spread_pct, flag_spread: rumus Excel. spread = realized tertinggi dikurangi terendah di antara provider yang memuat wallet.
A45: only_in: provider yang satu-satunya memuat wallet (hanya diisi bila >= 2 provider berhasil). Waspada: bisa karena daftar terpotong.
A46: role_disagreement: peran (dev, kol, smart_money, sniper, bundler, bot, arbitrage, pool_or_exchange) yang hanya dimiliki sebagian provider. Pemetaan label sederhana di suite/labels.py; hanya provider yang memberi label pada setidaknya satu wallet di run ini yang dibandingkan.
A47: sheet_row_*: nomor baris wallet di sheet mentah provider itu, untuk menelusuri angka ke sumbernya.

Sheet Gabungan
A1: wallet | B1: name | C1: n_sources | D1: sources | E1: rank_vybe | F1: rank_solanatracker | G1: rank_gmgn | H1: realized_vybe | I1: realized_solanatracker | J1: realized_gmgn | K1: spread_usd | L1: spread_pct | M1: flag_spread | N1: only_in | O1: role_disagreement | P1: labels_vybe | Q1: labels_solanatracker | R1: labels_gmgn | S1: funded_by_gmgn | T1: sheet_row_vybe | U1: sheet_row_solanatracker | V1: sheet_row_gmgn
A2: 8rvAsDKeAcEjEkiZMug9k8v1y8mW6gQQiMobd89Uy7qR | B2: Casino | C2: =COUNT(E2:G2) | D2: Vybe, SolanaTracker | E2: 1 | F2: 4 | H2: 2714.1185 | I2: 2687.3 | K2: =IF(COUNT(H2:J2)>=2,MAX(H2:J2)-MIN(H2:J2),"") | L2: =IF(ISNUMBER(K2),IF(MAX(ABS(MAX(H2:J2)),ABS(MIN(H2:J2)))=0,"",K2/MAX(ABS(MAX(H2:J2)),ABS(MIN(H2:J2)))),"") | M2: =IF(AND(ISNUMBER(K2),ISNUMBER(L2)),IF(AND(K2>=Ringkasan!$B$10,L2>=Ringkasan!$B$11),"yes",""),"") | P2: KOL | Q2: kol; terminal; axiom; pumpfun-app; bloom; sns | T2: 2 | U2: 5
A3: AVjEtg2ECYKXYeqdRQXvaaAZBjfTjYuSMTR4WLhKoeQN | B3: Putrick | C3: =COUNT(E3:G3) | D3: Vybe, SolanaTracker | E3: 3 | F3: 28 | H3: 974.79228 | I3: 970.55 | K3: =IF(COUNT(H3:J3)>=2,MAX(H3:J3)-MIN(H3:J3),"") | L3: =IF(ISNUMBER(K3),IF(MAX(ABS(MAX(H3:J3)),ABS(MIN(H3:J3)))=0,"",K3/MAX(ABS(MAX(H3:J3)),ABS(MIN(H3:J3)))),"") | M3: =IF(AND(ISNUMBER(K3),ISNUMBER(L3)),IF(AND(K3>=Ringkasan!$B$10,L3>=Ringkasan!$B$11),"yes",""),"") | P3: KOL | Q3: kol; axiom | T3: 4 | U3: 29
A4: HYSq1KBAvqWpEv1pCbV31muKM1za5A1WSHGdiVLUoNhb | B4: Apex 屮 | C4: =COUNT(E4:G4) | D4: Vybe, SolanaTracker | E4: 4 | F4: 29 | H4: 924.81458 | I4: 923.91 | K4: =IF(COUNT(H4:J4)>=2,MAX(H4:J4)-MIN(H4:J4),"") | L4: =IF(ISNUMBER(K4),IF(MAX(ABS(MAX(H4:J4)),ABS(MIN(H4:J4)))=0,"",K4/MAX(ABS(MAX(H4:J4)),ABS(MIN(H4:J4)))),"") | M4: =IF(AND(ISNUMBER(K4),ISNUMBER(L4)),IF(AND(K4>=Ringkasan!$B$10,L4>=Ringkasan!$B$11),"yes",""),"") | O4: kol (hanya Vybe) | P4: KOL | Q4: terminal; axiom; pumpfun-app | T4: 5 | U4: 30
A5: 39q2g5tTQn9n7KnuapzwS2smSx3NGYqBoea11tBjsGEt | B5: Walta | C5: =COUNT(E5:G5) | D5: Vybe, SolanaTracker | E5: 5 | F5: 36 | H5: 848.06988 | I5: 846.26 | K5: =IF(COUNT(H5:J5)>=2,MAX(H5:J5)-MIN(H5:J5),"") | L5: =IF(ISNUMBER(K5),IF(MAX(ABS(MAX(H5:J5)),ABS(MIN(H5:J5)))=0,"",K5/MAX(ABS(MAX(H5:J5)),ABS(MIN(H5:J5)))),"") | M5: =IF(AND(ISNUMBER(K5),ISNUMBER(L5)),IF(AND(K5>=Ringkasan!$B$10,L5>=Ringkasan!$B$11),"yes",""),"") | P5: KOL | Q5: kol; gmgn; photon | T5: 6 | U5: 37
A6: 3L8RAxLkvwkz4CgHivaVRtq19741FAdGLk5DgjRfc1fW | B6: Inquixit | C6: =COUNT(E6:G6) | D6: Vybe, SolanaTracker | E6: 6 | F6: 40 | H6: 780.72202 | I6: 780.84 | K6: =IF(COUNT(H6:J6)>=2,MAX(H6:J6)-MIN(H6:J6),"") | L6: =IF(ISNUMBER(K6),IF(MAX(ABS(MAX(H6:J6)),ABS(MIN(H6:J6)))=0,"",K6/MAX(ABS(MAX(H6:J6)),ABS(MIN(H6:J6)))),"") | M6: =IF(AND(ISNUMBER(K6),ISNUMBER(L6)),IF(AND(K6>=Ringkasan!$B$10,L6>=Ringkasan!$B$11),"yes",""),"") | P6: KOL | Q6: kol; terminal; axiom; bloom; sns | T6: 7 | U6: 41
A7: gangJEP5geDHjPVRhDS5dTF5e6GtRvtNogMEEVs91RV | B7: Qavec | C7: =COUNT(E7:G7) | D7: Vybe, SolanaTracker | E7: 15 | F7: 41 | H7: 137.33866 | I7: 770.68 | K7: =IF(COUNT(H7:J7)>=2,MAX(H7:J7)-MIN(H7:J7),"") | L7: =IF(ISNUMBER(K7),IF(MAX(ABS(MAX(H7:J7)),ABS(MIN(H7:J7)))=0,"",K7/MAX(ABS(MAX(H7:J7)),ABS(MIN(H7:J7)))),"") | M7: =IF(AND(ISNUMBER(K7),ISNUMBER(L7)),IF(AND(K7>=Ringkasan!$B$10,L7>=Ringkasan!$B$11),"yes",""),"") | P7: KOL | Q7: kol; terminal; axiom; pumpfun-app | T7: 16 | U7: 42
A8: 9tY7u1HgEt2RDcxym3RJ9sfvT3aZStiiUwXd44X9RUr8 | B8: Solana degen | C8: =COUNT(E8:G8) | D8: Vybe, SolanaTracker | E8: 7 | F8: 48 | H8: 684.20611 | I8: 684.11 | K8: =IF(COUNT(H8:J8)>=2,MAX(H8:J8)-MIN(H8:J8),"") | L8: =IF(ISNUMBER(K8),IF(MAX(ABS(MAX(H8:J8)),ABS(MIN(H8:J8)))=0,"",K8/MAX(ABS(MAX(H8:J8)),ABS(MIN(H8:J8)))),"") | M8: =IF(AND(ISNUMBER(K8),ISNUMBER(L8)),IF(AND(K8>=Ringkasan!$B$10,L8>=Ringkasan!$B$11),"yes",""),"") | P8: KOL | Q8: kol; axiom | T8: 8 | U8: 49
A9: BTf4A2exGK9BCVDNzy65b9dUzXgMqB4weVkvTMFQsadd | B9: Kev | C9: =COUNT(E9:G9) | D9: Vybe, SolanaTracker | E9: 8 | F9: 75 | H9: 491.60421 | I9: 491.28 | K9: =IF(COUNT(H9:J9)>=2,MAX(H9:J9)-MIN(H9:J9),"") | L9: =IF(ISNUMBER(K9),IF(MAX(ABS(MAX(H9:J9)),ABS(MIN(H9:J9)))=0,"",K9/MAX(ABS(MAX(H9:J9)),ABS(MIN(H9:J9)))),"") | M9: =IF(AND(ISNUMBER(K9),ISNUMBER(L9)),IF(AND(K9>=Ringkasan!$B$10,L9>=Ringkasan!$B$11),"yes",""),"") | P9: KOL | Q9: kol; gmgn; terminal; axiom; photon | T9: 9 | U9: 76
A10: 9LxMdvs1m8QRFvFuhvzzMXykAkpaHTJhktULdpBztUMm | C10: =COUNT(E10:G10) | D10: SolanaTracker | F10: 1 | I10: 5860.66 | K10: =IF(COUNT(H10:J10)>=2,MAX(H10:J10)-MIN(H10:J10),"") | L10: =IF(ISNUMBER(K10),IF(MAX(ABS(MAX(H10:J10)),ABS(MIN(H10:J10)))=0,"",K10/MAX(ABS(MAX(H10:J10)),ABS(MIN(H10:J10)))),"") | M10: =IF(AND(ISNUMBER(K10),ISNUMBER(L10)),IF(AND(K10>=Ringkasan!$B$10,L10>=Ringkasan!$B$11),"yes",""),"") | N10: SolanaTracker | Q10: axiom; bloom | U10: 2
A11: FASTESTv3ZKg9hbwQHf64pBfRxaD3NyP3exgCFhKeyX5 | C11: =COUNT(E11:G11) | D11: SolanaTracker | F11: 2 | I11: 3554.51 | K11: =IF(COUNT(H11:J11)>=2,MAX(H11:J11)-MIN(H11:J11),"") | L11: =IF(ISNUMBER(K11),IF(MAX(ABS(MAX(H11:J11)),ABS(MIN(H11:J11)))=0,"",K11/MAX(ABS(MAX(H11:J11)),ABS(MIN(H11:J11)))),"") | M11: =IF(AND(ISNUMBER(K11),ISNUMBER(L11)),IF(AND(K11>=Ringkasan!$B$10,L11>=Ringkasan!$B$11),"yes",""),"") | N11: SolanaTracker | Q11: axiom | U11: 3
A12: AH75Bn6QHSt5K2Ad4p1otns3JTwpSJWZTwiwKWNhmnKx | B12: bystevenr | C12: =COUNT(E12:G12) | D12: SolanaTracker | F12: 3 | I12: 3183.42 | K12: =IF(COUNT(H12:J12)>=2,MAX(H12:J12)-MIN(H12:J12),"") | L12: =IF(ISNUMBER(K12),IF(MAX(ABS(MAX(H12:J12)),ABS(MIN(H12:J12)))=0,"",K12/MAX(ABS(MAX(H12:J12)),ABS(MIN(H12:J12)))),"") | M12: =IF(AND(ISNUMBER(K12),ISNUMBER(L12)),IF(AND(K12>=Ringkasan!$B$10,L12>=Ringkasan!$B$11),"yes",""),"") | N12: SolanaTracker | Q12: fomo | U12: 4
A13: 6END8c4Xk81hHnwGT331W9bszBiEPBHkm4hWnZLNDfmp | C13: =COUNT(E13:G13) | D13: SolanaTracker | F13: 5 | I13: 2330.42 | K13: =IF(COUNT(H13:J13)>=2,MAX(H13:J13)-MIN(H13:J13),"") | L13: =IF(ISNUMBER(K13),IF(MAX(ABS(MAX(H13:J13)),ABS(MIN(H13:J13)))=0,"",K13/MAX(ABS(MAX(H13:J13)),ABS(MIN(H13:J13)))),"") | M13: =IF(AND(ISNUMBER(K13),ISNUMBER(L13)),IF(AND(K13>=Ringkasan!$B$10,L13>=Ringkasan!$B$11),"yes",""),"") | N13: SolanaTracker | Q13: axiom | U13: 6
A14: CLeLSah38ADw1gFR1ARb3F1zJYUrUsaTpNXQPgqqxDDd | C14: =COUNT(E14:G14) | D14: SolanaTracker | F14: 6 | I14: 2175.21 | K14: =IF(COUNT(H14:J14)>=2,MAX(H14:J14)-MIN(H14:J14),"") | L14: =IF(ISNUMBER(K14),IF(MAX(ABS(MAX(H14:J14)),ABS(MIN(H14:J14)))=0,"",K14/MAX(ABS(MAX(H14:J14)),ABS(MIN(H14:J14)))),"") | M14: =IF(AND(ISNUMBER(K14),ISNUMBER(L14)),IF(AND(K14>=Ringkasan!$B$10,L14>=Ringkasan!$B$11),"yes",""),"") | N14: SolanaTracker | Q14: fomo | U14: 7
A15: o997fRSR6LJmTbgjjf3QNSh6ZeEQ9AdmBJCLaokaFmu | C15: =COUNT(E15:G15) | D15: SolanaTracker | F15: 7 | I15: 2093.41 | K15: =IF(COUNT(H15:J15)>=2,MAX(H15:J15)-MIN(H15:J15),"") | L15: =IF(ISNUMBER(K15),IF(MAX(ABS(MAX(H15:J15)),ABS(MIN(H15:J15)))=0,"",K15/MAX(ABS(MAX(H15:J15)),ABS(MIN(H15:J15)))),"") | M15: =IF(AND(ISNUMBER(K15),ISNUMBER(L15)),IF(AND(K15>=Ringkasan!$B$10,L15>=Ringkasan!$B$11),"yes",""),"") | N15: SolanaTracker | Q15: fomo | U15: 8
A16: 4yo9CUuTBbds9NFhZd4MzPiZZkUvveXdTnAH8qMsE8ku | B16: Gfree | C16: =COUNT(E16:G16) | D16: Vybe | E16: 2 | H16: 1896.4555 | K16: =IF(COUNT(H16:J16)>=2,MAX(H16:J16)-MIN(H16:J16),"") | L16: =IF(ISNUMBER(K16),IF(MAX(ABS(MAX(H16:J16)),ABS(MIN(H16:J16)))=0,"",K16/MAX(ABS(MAX(H16:J16)),ABS(MIN(H16:J16)))),"") | M16: =IF(AND(ISNUMBER(K16),ISNUMBER(L16)),IF(AND(K16>=Ringkasan!$B$10,L16>=Ringkasan!$B$11),"yes",""),"") | N16: Vybe | P16: KOL | T16: 3
A17: 6NZWg24HVWuhPrNQuJ5bdxGYmUTrB62tAQEmHnyErErL | C17: =COUNT(E17:G17) | D17: SolanaTracker | F17: 8 | I17: 1864.46 | K17: =IF(COUNT(H17:J17)>=2,MAX(H17:J17)-MIN(H17:J17),"") | L17: =IF(ISNUMBER(K17),IF(MAX(ABS(MAX(H17:J17)),ABS(MIN(H17:J17)))=0,"",K17/MAX(ABS(MAX(H17:J17)),ABS(MIN(H17:J17)))),"") | M17: =IF(AND(ISNUMBER(K17),ISNUMBER(L17)),IF(AND(K17>=Ringkasan!$B$10,L17>=Ringkasan!$B$11),"yes",""),"") | N17: SolanaTracker | Q17: gmgn | U17: 9
A18: GunhR3usjEjQfiDe7ejuHZ9rGZ7BfZjGFXDr8AtcEzMR | C18: =COUNT(E18:G18) | D18: SolanaTracker | F18: 9 | I18: 1632.41 | K18: =IF(COUNT(H18:J18)>=2,MAX(H18:J18)-MIN(H18:J18),"") | L18: =IF(ISNUMBER(K18),IF(MAX(ABS(MAX(H18:J18)),ABS(MIN(H18:J18)))=0,"",K18/MAX(ABS(MAX(H18:J18)),ABS(MIN(H18:J18)))),"") | M18: =IF(AND(ISNUMBER(K18),ISNUMBER(L18)),IF(AND(K18>=Ringkasan!$B$10,L18>=Ringkasan!$B$11),"yes",""),"") | N18: SolanaTracker | Q18: axiom | U18: 10
A19: EFJxb2HNhpPKmfZzoXHLzokEf6gRdzs3Z3hLNxFBQyJm | B19: Harko | C19: =COUNT(E19:G19) | D19: SolanaTracker | F19: 10 | I19: 1533.83 | K19: =IF(COUNT(H19:J19)>=2,MAX(H19:J19)-MIN(H19:J19),"") | L19: =IF(ISNUMBER(K19),IF(MAX(ABS(MAX(H19:J19)),ABS(MIN(H19:J19)))=0,"",K19/MAX(ABS(MAX(H19:J19)),ABS(MIN(H19:J19)))),"") | M19: =IF(AND(ISNUMBER(K19),ISNUMBER(L19)),IF(AND(K19>=Ringkasan!$B$10,L19>=Ringkasan!$B$11),"yes",""),"") | N19: SolanaTracker | Q19: fomo | U19: 11
A20: 6cLXobwM9PkXaiV2hFg2FwAH5eAUuodgQWNU7vAQESBC | C20: =COUNT(E20:G20) | D20: SolanaTracker | F20: 11 | I20: 1523.27 | K20: =IF(COUNT(H20:J20)>=2,MAX(H20:J20)-MIN(H20:J20),"") | L20: =IF(ISNUMBER(K20),IF(MAX(ABS(MAX(H20:J20)),ABS(MIN(H20:J20)))=0,"",K20/MAX(ABS(MAX(H20:J20)),ABS(MIN(H20:J20)))),"") | M20: =IF(AND(ISNUMBER(K20),ISNUMBER(L20)),IF(AND(K20>=Ringkasan!$B$10,L20>=Ringkasan!$B$11),"yes",""),"") | N20: SolanaTracker | Q20: axiom | U20: 12
A21: EU8f7oUVEFKYBymLYkDihr8LemRySsoHiy3TaHbnTD9X | C21: =COUNT(E21:G21) | D21: SolanaTracker | F21: 12 | I21: 1409.91 | K21: =IF(COUNT(H21:J21)>=2,MAX(H21:J21)-MIN(H21:J21),"") | L21: =IF(ISNUMBER(K21),IF(MAX(ABS(MAX(H21:J21)),ABS(MIN(H21:J21)))=0,"",K21/MAX(ABS(MAX(H21:J21)),ABS(MIN(H21:J21)))),"") | M21: =IF(AND(ISNUMBER(K21),ISNUMBER(L21)),IF(AND(K21>=Ringkasan!$B$10,L21>=Ringkasan!$B$11),"yes",""),"") | N21: SolanaTracker | Q21: axiom | U21: 13
A22: BSsyo5oh2tuaZBjjWq6V3NHS66BTHfmV1aJd6RDyknLQ | B22: Clark 🆓 | C22: =COUNT(E22:G22) | D22: SolanaTracker | F22: 13 | I22: 1408.69 | K22: =IF(COUNT(H22:J22)>=2,MAX(H22:J22)-MIN(H22:J22),"") | L22: =IF(ISNUMBER(K22),IF(MAX(ABS(MAX(H22:J22)),ABS(MIN(H22:J22)))=0,"",K22/MAX(ABS(MAX(H22:J22)),ABS(MIN(H22:J22)))),"") | M22: =IF(AND(ISNUMBER(K22),ISNUMBER(L22)),IF(AND(K22>=Ringkasan!$B$10,L22>=Ringkasan!$B$11),"yes",""),"") | N22: SolanaTracker | Q22: fomo | U22: 14
A23: 9sqBx1FqZqTi1Zo4TpRamwQDED7wgeueh7wSUyxhKpJE | C23: =COUNT(E23:G23) | D23: SolanaTracker | F23: 14 | I23: 1379.73 | K23: =IF(COUNT(H23:J23)>=2,MAX(H23:J23)-MIN(H23:J23),"") | L23: =IF(ISNUMBER(K23),IF(MAX(ABS(MAX(H23:J23)),ABS(MIN(H23:J23)))=0,"",K23/MAX(ABS(MAX(H23:J23)),ABS(MIN(H23:J23)))),"") | M23: =IF(AND(ISNUMBER(K23),ISNUMBER(L23)),IF(AND(K23>=Ringkasan!$B$10,L23>=Ringkasan!$B$11),"yes",""),"") | N23: SolanaTracker | Q23: axiom | U23: 15
A24: 6SHqkzJfZYiNqmz4xDiwndEAqbubuAVt44LwJ9GF3obS | B24: ocr ⚘ | C24: =COUNT(E24:G24) | D24: SolanaTracker | F24: 15 | I24: 1243.76 | K24: =IF(COUNT(H24:J24)>=2,MAX(H24:J24)-MIN(H24:J24),"") | L24: =IF(ISNUMBER(K24),IF(MAX(ABS(MAX(H24:J24)),ABS(MIN(H24:J24)))=0,"",K24/MAX(ABS(MAX(H24:J24)),ABS(MIN(H24:J24)))),"") | M24: =IF(AND(ISNUMBER(K24),ISNUMBER(L24)),IF(AND(K24>=Ringkasan!$B$10,L24>=Ringkasan!$B$11),"yes",""),"") | N24: SolanaTracker | Q24: axiom; fomo | U24: 16
A25: DPQXGSpn4NXJxUNRwzAJ84CuufM83mToiJseVwPRKL3u | B25: jaq | C25: =COUNT(E25:G25) | D25: SolanaTracker | F25: 16 | I25: 1222.39 | K25: =IF(COUNT(H25:J25)>=2,MAX(H25:J25)-MIN(H25:J25),"") | L25: =IF(ISNUMBER(K25),IF(MAX(ABS(MAX(H25:J25)),ABS(MIN(H25:J25)))=0,"",K25/MAX(ABS(MAX(H25:J25)),ABS(MIN(H25:J25)))),"") | M25: =IF(AND(ISNUMBER(K25),ISNUMBER(L25)),IF(AND(K25>=Ringkasan!$B$10,L25>=Ringkasan!$B$11),"yes",""),"") | N25: SolanaTracker | Q25: axiom; fomo | U25: 17
A26: HTYho9ioTJcS4Dymi57HB65RBFu549gjyQ7kncfkknti | B26: BrazilZZ🇧🇷 | C26: =COUNT(E26:G26) | D26: SolanaTracker | F26: 17 | I26: 1194.31 | K26: =IF(COUNT(H26:J26)>=2,MAX(H26:J26)-MIN(H26:J26),"") | L26: =IF(ISNUMBER(K26),IF(MAX(ABS(MAX(H26:J26)),ABS(MIN(H26:J26)))=0,"",K26/MAX(ABS(MAX(H26:J26)),ABS(MIN(H26:J26)))),"") | M26: =IF(AND(ISNUMBER(K26),ISNUMBER(L26)),IF(AND(K26>=Ringkasan!$B$10,L26>=Ringkasan!$B$11),"yes",""),"") | N26: SolanaTracker | Q26: fomo | U26: 18
A27: 5dQJ5xZZ1qjcLDZ8PDqymMeKzBDnLFjtzmJv4aCfpui8 | C27: =COUNT(E27:G27) | D27: SolanaTracker | F27: 18 | I27: 1159.82 | K27: =IF(COUNT(H27:J27)>=2,MAX(H27:J27)-MIN(H27:J27),"") | L27: =IF(ISNUMBER(K27),IF(MAX(ABS(MAX(H27:J27)),ABS(MIN(H27:J27)))=0,"",K27/MAX(ABS(MAX(H27:J27)),ABS(MIN(H27:J27)))),"") | M27: =IF(AND(ISNUMBER(K27),ISNUMBER(L27)),IF(AND(K27>=Ringkasan!$B$10,L27>=Ringkasan!$B$11),"yes",""),"") | N27: SolanaTracker | Q27: axiom | U27: 19
A28: 7D5fAcz2LTARqPc7D1L2aVFDajizw358PV4tPCTDJpE5 | B28: The Night Owl | C28: =COUNT(E28:G28) | D28: SolanaTracker | F28: 19 | I28: 1137.87 | K28: =IF(COUNT(H28:J28)>=2,MAX(H28:J28)-MIN(H28:J28),"") | L28: =IF(ISNUMBER(K28),IF(MAX(ABS(MAX(H28:J28)),ABS(MIN(H28:J28)))=0,"",K28/MAX(ABS(MAX(H28:J28)),ABS(MIN(H28:J28)))),"") | M28: =IF(AND(ISNUMBER(K28),ISNUMBER(L28)),IF(AND(K28>=Ringkasan!$B$10,L28>=Ringkasan!$B$11),"yes",""),"") | N28: SolanaTracker | Q28: potential_bot; fomo | U28: 20
A29: HB3GebzspXg5PBpeqewkjHPxugf4Uhx8xdZWGPC9q5ks | B29: snacky14 | C29: =COUNT(E29:G29) | D29: SolanaTracker | F29: 20 | I29: 1120.56 | K29: =IF(COUNT(H29:J29)>=2,MAX(H29:J29)-MIN(H29:J29),"") | L29: =IF(ISNUMBER(K29),IF(MAX(ABS(MAX(H29:J29)),ABS(MIN(H29:J29)))=0,"",K29/MAX(ABS(MAX(H29:J29)),ABS(MIN(H29:J29)))),"") | M29: =IF(AND(ISNUMBER(K29),ISNUMBER(L29)),IF(AND(K29>=Ringkasan!$B$10,L29>=Ringkasan!$B$11),"yes",""),"") | N29: SolanaTracker | Q29: axiom; pumpfun-app | U29: 21
A30: 6qtsui7ntgkDyB1YzokZAmDeBRTe1GcWTpT76uKpPBPu | C30: =COUNT(E30:G30) | D30: SolanaTracker | F30: 21 | I30: 1110.46 | K30: =IF(COUNT(H30:J30)>=2,MAX(H30:J30)-MIN(H30:J30),"") | L30: =IF(ISNUMBER(K30),IF(MAX(ABS(MAX(H30:J30)),ABS(MIN(H30:J30)))=0,"",K30/MAX(ABS(MAX(H30:J30)),ABS(MIN(H30:J30)))),"") | M30: =IF(AND(ISNUMBER(K30),ISNUMBER(L30)),IF(AND(K30>=Ringkasan!$B$10,L30>=Ringkasan!$B$11),"yes",""),"") | N30: SolanaTracker | Q30: axiom | U30: 22
A31: 3YRuiSpoPpxjrdZMTQvXVK2v4Cjdy6ZTzV5NpxSaW4gQ | C31: =COUNT(E31:G31) | D31: SolanaTracker | F31: 22 | I31: 1054.96 | K31: =IF(COUNT(H31:J31)>=2,MAX(H31:J31)-MIN(H31:J31),"") | L31: =IF(ISNUMBER(K31),IF(MAX(ABS(MAX(H31:J31)),ABS(MIN(H31:J31)))=0,"",K31/MAX(ABS(MAX(H31:J31)),ABS(MIN(H31:J31)))),"") | M31: =IF(AND(ISNUMBER(K31),ISNUMBER(L31)),IF(AND(K31>=Ringkasan!$B$10,L31>=Ringkasan!$B$11),"yes",""),"") | N31: SolanaTracker | Q31: axiom; bloom | U31: 23
A32: FSHXkmt8TPdwE3Qe9xxpX7QFVfJC4YfdDsCzZmM2G2Wi | B32: neverforever.sol | C32: =COUNT(E32:G32) | D32: SolanaTracker | F32: 23 | I32: 1017.8 | K32: =IF(COUNT(H32:J32)>=2,MAX(H32:J32)-MIN(H32:J32),"") | L32: =IF(ISNUMBER(K32),IF(MAX(ABS(MAX(H32:J32)),ABS(MIN(H32:J32)))=0,"",K32/MAX(ABS(MAX(H32:J32)),ABS(MIN(H32:J32)))),"") | M32: =IF(AND(ISNUMBER(K32),ISNUMBER(L32)),IF(AND(K32>=Ringkasan!$B$10,L32>=Ringkasan!$B$11),"yes",""),"") | N32: SolanaTracker | Q32: axiom; sns | U32: 24
A33: 9NVFdRNEcreYDZqJAhennP2tTzaiNC2p9h9HWTdjLBuB | C33: =COUNT(E33:G33) | D33: SolanaTracker | F33: 24 | I33: 1006.62 | K33: =IF(COUNT(H33:J33)>=2,MAX(H33:J33)-MIN(H33:J33),"") | L33: =IF(ISNUMBER(K33),IF(MAX(ABS(MAX(H33:J33)),ABS(MIN(H33:J33)))=0,"",K33/MAX(ABS(MAX(H33:J33)),ABS(MIN(H33:J33)))),"") | M33: =IF(AND(ISNUMBER(K33),ISNUMBER(L33)),IF(AND(K33>=Ringkasan!$B$10,L33>=Ringkasan!$B$11),"yes",""),"") | N33: SolanaTracker | Q33: axiom; fomo | U33: 25
A34: DFvoyXaNPANK9ENGekE88FALjt2CMHWspZKTg62hJJ1Z | C34: =COUNT(E34:G34) | D34: SolanaTracker | F34: 25 | I34: 998.59 | K34: =IF(COUNT(H34:J34)>=2,MAX(H34:J34)-MIN(H34:J34),"") | L34: =IF(ISNUMBER(K34),IF(MAX(ABS(MAX(H34:J34)),ABS(MIN(H34:J34)))=0,"",K34/MAX(ABS(MAX(H34:J34)),ABS(MIN(H34:J34)))),"") | M34: =IF(AND(ISNUMBER(K34),ISNUMBER(L34)),IF(AND(K34>=Ringkasan!$B$10,L34>=Ringkasan!$B$11),"yes",""),"") | N34: SolanaTracker | Q34: fomo | U34: 26
A35: DEdwtjvCs6dSadA8b6EQwCP95mXebTqMDK6wh13xhdpR | C35: =COUNT(E35:G35) | D35: SolanaTracker | F35: 26 | I35: 989.4 | K35: =IF(COUNT(H35:J35)>=2,MAX(H35:J35)-MIN(H35:J35),"") | L35: =IF(ISNUMBER(K35),IF(MAX(ABS(MAX(H35:J35)),ABS(MIN(H35:J35)))=0,"",K35/MAX(ABS(MAX(H35:J35)),ABS(MIN(H35:J35)))),"") | M35: =IF(AND(ISNUMBER(K35),ISNUMBER(L35)),IF(AND(K35>=Ringkasan!$B$10,L35>=Ringkasan!$B$11),"yes",""),"") | N35: SolanaTracker | Q35: terminal; axiom | U35: 27
A36: GNJmDgfMeVD5gvfSFSyJzCXnFNSxM5xhnzSToTQ4YbUz | C36: =COUNT(E36:G36) | D36: SolanaTracker | F36: 27 | I36: 983.76 | K36: =IF(COUNT(H36:J36)>=2,MAX(H36:J36)-MIN(H36:J36),"") | L36: =IF(ISNUMBER(K36),IF(MAX(ABS(MAX(H36:J36)),ABS(MIN(H36:J36)))=0,"",K36/MAX(ABS(MAX(H36:J36)),ABS(MIN(H36:J36)))),"") | M36: =IF(AND(ISNUMBER(K36),ISNUMBER(L36)),IF(AND(K36>=Ringkasan!$B$10,L36>=Ringkasan!$B$11),"yes",""),"") | N36: SolanaTracker | Q36: axiom | U36: 28
A37: 5d3HHrbc9Ho48jibqiVM5GJi7cuL3p17SiJkc1y8qrQ3 | C37: =COUNT(E37:G37) | D37: SolanaTracker | F37: 30 | I37: 916.13 | K37: =IF(COUNT(H37:J37)>=2,MAX(H37:J37)-MIN(H37:J37),"") | L37: =IF(ISNUMBER(K37),IF(MAX(ABS(MAX(H37:J37)),ABS(MIN(H37:J37)))=0,"",K37/MAX(ABS(MAX(H37:J37)),ABS(MIN(H37:J37)))),"") | M37: =IF(AND(ISNUMBER(K37),ISNUMBER(L37)),IF(AND(K37>=Ringkasan!$B$10,L37>=Ringkasan!$B$11),"yes",""),"") | N37: SolanaTracker | Q37: axiom | U37: 31
A38: BWiJ8aqkhSQx55KA4mB8KXv82ga2972tLtgpAZiuocrU | C38: =COUNT(E38:G38) | D38: SolanaTracker | F38: 31 | I38: 914.37 | K38: =IF(COUNT(H38:J38)>=2,MAX(H38:J38)-MIN(H38:J38),"") | L38: =IF(ISNUMBER(K38),IF(MAX(ABS(MAX(H38:J38)),ABS(MIN(H38:J38)))=0,"",K38/MAX(ABS(MAX(H38:J38)),ABS(MIN(H38:J38)))),"") | M38: =IF(AND(ISNUMBER(K38),ISNUMBER(L38)),IF(AND(K38>=Ringkasan!$B$10,L38>=Ringkasan!$B$11),"yes",""),"") | N38: SolanaTracker | Q38: terminal; axiom | U38: 32
A39: 6AKrfdeLdgsR1NJjSEih7rajxv8AQvrkmmhn9HMuqrcf | C39: =COUNT(E39:G39) | D39: SolanaTracker | F39: 32 | I39: 898.4 | K39: =IF(COUNT(H39:J39)>=2,MAX(H39:J39)-MIN(H39:J39),"") | L39: =IF(ISNUMBER(K39),IF(MAX(ABS(MAX(H39:J39)),ABS(MIN(H39:J39)))=0,"",K39/MAX(ABS(MAX(H39:J39)),ABS(MIN(H39:J39)))),"") | M39: =IF(AND(ISNUMBER(K39),ISNUMBER(L39)),IF(AND(K39>=Ringkasan!$B$10,L39>=Ringkasan!$B$11),"yes",""),"") | N39: SolanaTracker | Q39: potential_bot | U39: 33
A40: 9eUx1DGDzAQuEXR9pSR9u3QworFT8TRgFJatcCiXNURS | B40: Tristan | C40: =COUNT(E40:G40) | D40: SolanaTracker | F40: 33 | I40: 883.38 | K40: =IF(COUNT(H40:J40)>=2,MAX(H40:J40)-MIN(H40:J40),"") | L40: =IF(ISNUMBER(K40),IF(MAX(ABS(MAX(H40:J40)),ABS(MIN(H40:J40)))=0,"",K40/MAX(ABS(MAX(H40:J40)),ABS(MIN(H40:J40)))),"") | M40: =IF(AND(ISNUMBER(K40),ISNUMBER(L40)),IF(AND(K40>=Ringkasan!$B$10,L40>=Ringkasan!$B$11),"yes",""),"") | N40: SolanaTracker | Q40: fomo | U40: 34
...

Sheet Vybe
A1: rank | B1: trader_address | C1: name | D1: labels | E1: realized_pnl_usd
A2: 1 | B2: 8rvAsDKeAcEjEkiZMug9k8v1y8mW6gQQiMobd89Uy7qR | C2: Casino | D2: KOL | E2: 2714.1185
A3: 2 | B3: 4yo9CUuTBbds9NFhZd4MzPiZZkUvveXdTnAH8qMsE8ku | C3: Gfree | D3: KOL | E3: 1896.4555
A4: 3 | B4: AVjEtg2ECYKXYeqdRQXvaaAZBjfTjYuSMTR4WLhKoeQN | C4: Putrick | D4: KOL | E4: 974.79228
A5: 4 | B5: HYSq1KBAvqWpEv1pCbV31muKM1za5A1WSHGdiVLUoNhb | C5: Apex 屮 | D5: KOL | E5: 924.81458
A6: 5 | B6: 39q2g5tTQn9n7KnuapzwS2smSx3NGYqBoea11tBjsGEt | C6: Walta | D6: KOL | E6: 848.06988
A7: 6 | B7: 3L8RAxLkvwkz4CgHivaVRtq19741FAdGLk5DgjRfc1fW | C7: Inquixit | D7: KOL | E7: 780.72202
A8: 7 | B8: 9tY7u1HgEt2RDcxym3RJ9sfvT3aZStiiUwXd44X9RUr8 | C8: Solana degen | D8: KOL | E8: 684.20611
A9: 8 | B9: BTf4A2exGK9BCVDNzy65b9dUzXgMqB4weVkvTMFQsadd | C9: Kev | D9: KOL | E9: 491.60421
A10: 9 | B10: 8fsKLLtvKNanL4ginCaiRS6UfeemY11rSf8U8fN1dJw4 | C10: Stigman | D10: KOL | E10: 312.93133
A11: 10 | B11: EeXvxkcGqMDZeTaVeawzxm9mbzZwqDUMmfG3bF7uzumH | C11: milito | D11: KOL | E11: 300.73354
A12: 11 | B12: 5vg7he5HibvsAW86wfiuP6jw7VwKmUAnP6P93mVCdpJu | C12: blixze ♱ | D12: KOL | E12: 253.14857
A13: 12 | B13: 4S8YBCt6hhi7Nr1NnKF6jF856LLN8JJFzD1a8nF5UuHA | C13: shaka | D13: KOL | E13: 230.64957
A14: 13 | B14: 9iaawVBEsFG35PSwd4PahwT8fYNQe9XYuRdWm872dUqY | C14: Meechie | D14: KOL | E14: 203.03593
A15: 14 | B15: 9B3XkfDxCG3QBrVMEDMVNzJn5tJsGkERWMAypC98PkEH | E15: 184.65304
A16: 15 | B16: gangJEP5geDHjPVRhDS5dTF5e6GtRvtNogMEEVs91RV | C16: Qavec | D16: KOL | E16: 137.33866
A17: 16 | B17: 6uCmBAxg9kgyiyzPs2XhYjebiadWwDxnmkMJ1djYBB1 | E17: 115.6291
A18: 17 | B18: 8CCb5QnL2viBUDvb6piyuawe7h4WwP2RdAiN52au22Wh | E18: 113.75503
A19: 18 | B19: 9aGU3qY1e1b2eYikui8n8FK2pLhwWmFV2j1RALFQcfCX | E19: 87.44444
A20: 19 | B20: Bjka6ui7kf8coVg7aC6TQC6736TZvSdcyHBPQczF5RG9 | E20: 85.978943
A21: 20 | B21: 87YAxAWhwp4hiTuJrMpRBL4tY9FFWpv4XXCR2PbdLgKa | E21: 70.930526
A22: 21 | B22: EQaxqKT3N981QBmdSUGNzAGK5S26zUwAdRHhBCgn87zD | C22: jamessmith | D22: KOL | E22: 53.7073
A23: 22 | B23: 9WgWgxxqgvYjNHeHm3Nci2JmF35hTf7Ri3qX2gV2fivX | E23: 50.474959
A24: 23 | B24: DW21bL8PyH1dNKtJBMLSZ227iyKT1kUzWHJV55hKNhf6 | E24: 39.872889
A25: 24 | B25: 7Js5gmq57y9jG2sseKrAeJt3vbncSWSFFHDEsyJDnyVm | C25: Yami 𓃵 | D25: KOL | E25: 35.641149
A26: 25 | B26: DzgANUkdPBYCN2Z65aVMsMWPNNJT9c4KhBTXtBwzaPnH | E26: 29.718588
A27: 26 | B27: Dw54DCQwJMNegyF2MJFrhevgeuNxkFZ4FNp1yGgycHN9 | E27: 25.686946
A28: 27 | B28: GXhR4ax3eUuKFgqo5z7nSusD4PCbZ6Q2dobuy6taM4wb | E28: 24.089801
A29: 28 | B29: 99i9uVA7Q56bY22ajKKUfTZTgTeP5yCtVGsrG9J4pDYQ | C29: Zrool 尔 | D29: KOL | E29: 23.79783
A30: 29 | B30: EB1pXGLBpyTEWGNZVgw1rcuhSYAk2dkwnRx9r1A6QWME | E30: 23.36355
A31: 30 | B31: DZyGibU23LEkE2452Pr6YKdz1W6wA2jmhVfHSZNTEx4N | E31: 23.074786
A32: 31 | B32: 6p4MnFpQv8yf1xJhvQDnUDKbBKzyPnGx9KffmWvUYpt1 | E32: 21.725653
A33: 32 | B33: 9WY8vHeTvkDvaxEsGg1jz1QbAduggADfX8wL6hykcPna | E33: 18.632722
A34: 33 | B34: 4e4rn7UpaRcjK3BFsZijz9schkQEB3boKKdW9824GHp6 | E34: 13.957776
A35: 34 | B35: G9wcxXBmqaDS1BTLULCdYkWYktqsXTicd5Qyk7DHiYTZ | E35: 12.681756
A36: 35 | B36: 3J4mqL4tY6SyTWu9gPs4KFaX54TZZJNNfzxxjFGDQzUN | E36: 12.397127
A37: 36 | B37: D8pdbmmivyt3UY7tZcjfQPMsLfNZTYdYpu1MFd17jxiX | E37: 11.46664
A38: 37 | B38: FKFyY4cmnShXswyh7QizNdEDznqegQMEdAZcvkUiZLSk | E38: 10.474009
A39: 38 | B39: 4vXxDXZ6cbnpG8gRFxw4UxrHa5W5nW1xE1zmWfU9b9PK | E39: 9.463115
A40: 39 | B40: 5GW4Gk5JbkHxiyrXeuBejCeVnK7GSTyMcQ5Wf3jD1Qnt | E40: 8.2378672
...

Sheet SolanaTracker
A1: rank | B1: wallet | C1: labels | D1: identity_name | E1: realized_pnl_usd | F1: unrealized_pnl_usd | G1: total_pnl_usd | H1: roi | I1: invested_usd | J1: proceeds_usd | K1: buys | L1: sells | M1: first_trade_utc | N1: last_trade_utc | O1: hold_time_secs | P1: balance | Q1: value_usd | R1: wallet_lifetime_realized_pnl_usd | S1: wallet_lifetime_trades | T1: wallet_tokens_traded
A2: 1 | B2: 9LxMdvs1m8QRFvFuhvzzMXykAkpaHTJhktULdpBztUMm | C2: axiom;bloom | E2: 5860.66 | F2: 0 | G2: 5860.66 | H2: 1925.12 | I2: 304.43 | J2: 6165.09 | K2: 1 | L2: 25 | M2: 2026-10-15T05:00:50Z | N2: 2026-10-15T05:34:59Z | O2: 2049 | P2: 0 | Q2: 0 | R2: 532689.12 | S2: 62159 | T2: 6698
A3: 2 | B3: FASTESTv3ZKg9hbwQHf64pBfRxaD3NyP3exgCFhKeyX5 | C3: axiom | E3: 3554.51 | F3: 0 | G3: 3554.51 | H3: 0 | I3: 0 | J3: 3554.51 | K3: 0 | L3: 7 | M3: 2026-10-15T05:41:23Z | N3: 2026-10-15T05:42:46Z | P3: 0 | Q3: 0 | R3: 56045.82 | S3: 8159 | T3: 1475
A4: 3 | B4: AH75Bn6QHSt5K2Ad4p1otns3JTwpSJWZTwiwKWNhmnKx | C4: fomo | D4: bystevenr | E4: 3183.42 | F4: 0 | G4: 3183.42 | H4: 127.67 | I4: 2493.41 | J4: 5676.83 | K4: 4 | L4: 1 | M4: 2026-10-15T05:11:53Z | N4: 2026-10-15T05:34:56Z | O4: 1383 | P4: 0 | Q4: 0 | R4: 121907.1 | S4: 2586 | T4: 450
A5: 4 | B5: 8rvAsDKeAcEjEkiZMug9k8v1y8mW6gQQiMobd89Uy7qR | C5: kol;terminal;axiom;pumpfun-app;bloom;sns | D5: Casino | E5: 2687.3 | F5: 0 | G5: 2687.3 | H5: 229.78 | I5: 1169.5 | J5: 3856.8 | K5: 5 | L5: 5 | M5: 2026-10-15T05:05:15Z | N5: 2026-10-15T05:17:12Z | O5: 716 | P5: 0 | Q5: 0 | R5: 4109748.6 | S5: 188697 | T5: 41142
A6: 5 | B6: 6END8c4Xk81hHnwGT331W9bszBiEPBHkm4hWnZLNDfmp | C6: axiom | E6: 2330.42 | F6: 0 | G6: 2330.42 | H6: 228.72 | I6: 1018.9 | J6: 3349.32 | K6: 2 | L6: 17 | M6: 2026-10-15T05:10:45Z | N6: 2026-10-15T05:24:13Z | O6: 4515 | P6: 2.793968e-09 | Q6: 0 | R6: 23043.03 | S6: 1206 | T6: 175
A7: 6 | B7: CLeLSah38ADw1gFR1ARb3F1zJYUrUsaTpNXQPgqqxDDd | C7: fomo | E7: 2175.21 | F7: 0 | G7: 2175.21 | H7: 201.64 | I7: 1078.77 | J7: 3253.99 | K7: 2 | L7: 5 | M7: 2026-10-15T05:01:43Z | N7: 2026-10-15T05:34:20Z | O7: 1957 | P7: 0 | Q7: 0 | R7: -102.17 | S7: 622 | T7: 120
A8: 7 | B8: o997fRSR6LJmTbgjjf3QNSh6ZeEQ9AdmBJCLaokaFmu | C8: fomo | E8: 2093.41 | F8: 1288.71 | G8: 3382.13 | H8: 666.42 | I8: 507.51 | J8: 2372.47 | K8: 2 | L8: 2 | M8: 2026-10-15T05:04:28Z | N8: 2026-10-15T05:34:40Z | O8: 4891 | P8: 6194219.2 | Q8: 1517.17 | R8: 6124.73 | S8: 270 | T8: 87
A9: 8 | B9: 6NZWg24HVWuhPrNQuJ5bdxGYmUTrB62tAQEmHnyErErL | C9: gmgn | E9: 1864.46 | F9: 0 | G9: 1864.46 | H9: 599.69 | I9: 310.91 | J9: 2175.36 | K9: 3 | L9: 6 | M9: 2026-10-15T05:01:30Z | N9: 2026-10-15T05:25:37Z | O9: 1447 | P9: 0 | Q9: 0 | R9: 3136.28 | S9: 257 | T9: 71
A10: 9 | B10: GunhR3usjEjQfiDe7ejuHZ9rGZ7BfZjGFXDr8AtcEzMR | C10: axiom | E10: 1632.41 | F10: 0 | G10: 1632.41 | H10: 0 | I10: 0 | J10: 1632.41 | K10: 0 | L10: 15 | M10: 2026-10-15T05:12:12Z | N10: 2026-10-15T05:12:17Z | P10: 0 | Q10: 0 | R10: -9380.74 | S10: 9724 | T10: 1622
A11: 10 | B11: EFJxb2HNhpPKmfZzoXHLzokEf6gRdzs3Z3hLNxFBQyJm | C11: fomo | D11: Harko | E11: 1533.83 | F11: 0 | G11: 1533.83 | H11: 139.46 | I11: 1099.84 | J11: 2633.67 | K11: 2 | L11: 4 | M11: 2026-10-15T05:08:22Z | N11: 2026-10-15T05:34:22Z | O11: 1560 | P11: 0 | Q11: 0 | R11: 35385.64 | S11: 1823 | T11: 387
A12: 11 | B12: 6cLXobwM9PkXaiV2hFg2FwAH5eAUuodgQWNU7vAQESBC | C12: axiom | E12: 1523.27 | F12: 8.85 | G12: 1532.12 | H12: 137.18 | I12: 1116.89 | J12: 2085.89 | K12: 32 | L12: 5 | M12: 2026-10-15T05:00:26Z | N12: 2026-10-15T06:25:01Z | O12: 5134 | P12: 2299040.4 | Q12: 563.11 | R12: 908.34 | S12: 177 | T12: 29
A13: 12 | B13: EU8f7oUVEFKYBymLYkDihr8LemRySsoHiy3TaHbnTD9X | C13: axiom | E13: 1409.91 | F13: 0 | G13: 1409.91 | H13: 775.96 | I13: 181.7 | J13: 1591.6 | K13: 9 | L13: 34 | M13: 2026-10-15T04:58:38Z | N13: 2026-10-15T05:19:50Z | O13: 1272 | P13: 0 | Q13: 0 | R13: 82829.89 | S13: 32322 | T13: 6554
A14: 13 | B14: BSsyo5oh2tuaZBjjWq6V3NHS66BTHfmV1aJd6RDyknLQ | C14: fomo | D14: Clark 🆓 | E14: 1408.69 | F14: 733.87 | G14: 2142.55 | H14: 119.03 | I14: 1800 | J14: 2408.69 | K14: 6 | L14: 3 | M14: 2026-10-15T05:11:38Z | N14: 2026-10-15T05:46:15Z | O14: 4461 | P14: 6262404.2 | Q14: 1533.87 | R14: 132264.79 | S14: 2055 | T14: 414
A15: 14 | B15: 9sqBx1FqZqTi1Zo4TpRamwQDED7wgeueh7wSUyxhKpJE | C15: axiom | E15: 1379.73 | F15: 0 | G15: 1379.73 | H15: 683.47 | I15: 201.87 | J15: 1581.6 | K15: 9 | L15: 34 | M15: 2026-10-15T04:58:38Z | N15: 2026-10-15T05:19:50Z | O15: 1272 | P15: 0 | Q15: 0 | R15: 75993.37 | S15: 32216 | T15: 6552
A16: 15 | B16: 6SHqkzJfZYiNqmz4xDiwndEAqbubuAVt44LwJ9GF3obS | C16: axiom;fomo | D16: ocr ⚘ | E16: 1243.76 | F16: 0 | G16: 1243.76 | H16: 46.07 | I16: 2700 | J16: 3943.76 | K16: 7 | L16: 1 | M16: 2026-10-15T05:13:26Z | N16: 2026-10-15T05:34:21Z | O16: 1255 | P16: 0 | Q16: 0 | R16: -127952.33 | S16: 7375 | T16: 1714
A17: 16 | B17: DPQXGSpn4NXJxUNRwzAJ84CuufM83mToiJseVwPRKL3u | C17: axiom;fomo | D17: jaq | E17: 1222.39 | F17: 0 | G17: 1222.39 | H17: 35.98 | I17: 3397 | J17: 4619.4 | K17: 10 | L17: 4 | M17: 2026-10-15T05:06:05Z | N17: 2026-10-15T05:51:00Z | O17: 2695 | P17: 0 | Q17: 0 | R17: -188691.37 | S17: 1820 | T17: 309
A18: 17 | B18: HTYho9ioTJcS4Dymi57HB65RBFu549gjyQ7kncfkknti | C18: fomo | D18: BrazilZZ🇧🇷 | E18: 1194.31 | F18: 0 | G18: 1194.31 | H18: 47.78 | I18: 2499.4 | J18: 3693.71 | K18: 3 | L18: 3 | M18: 2026-10-15T05:12:10Z | N18: 2026-10-15T05:35:01Z | O18: 1372 | P18: 0 | Q18: 0 | R18: -70813.56 | S18: 10328 | T18: 2033
A19: 18 | B19: 5dQJ5xZZ1qjcLDZ8PDqymMeKzBDnLFjtzmJv4aCfpui8 | C19: axiom | E19: 1159.82 | F19: 0 | G19: 1159.82 | H19: 619.02 | I19: 187.36 | J19: 1347.18 | K19: 9 | L19: 34 | M19: 2026-10-15T04:58:38Z | N19: 2026-10-15T05:19:50Z | O19: 1272 | P19: 0 | Q19: 0 | R19: 89790.61 | S19: 32281 | T19: 6556
A20: 19 | B20: 7D5fAcz2LTARqPc7D1L2aVFDajizw358PV4tPCTDJpE5 | C20: potential_bot;fomo | D20: The Night Owl | E20: 1137.87 | F20: 3036.35 | G20: 4174.22 | H20: 196.71 | I20: 2122 | J20: 1628.17 | K20: 10 | L20: 2 | M20: 2026-10-15T05:10:17Z | N20: 2026-10-15T05:54:29Z | O20: 4542 | P20: 19058507 | Q20: 4668.05 | R20: 39368.03 | S20: 3914 | T20: 700
A21: 20 | B21: HB3GebzspXg5PBpeqewkjHPxugf4Uhx8xdZWGPC9q5ks | C21: axiom;pumpfun-app | D21: snacky14 | E21: 1120.56 | F21: 0 | G21: 1120.56 | H21: 78.73 | I21: 1423.3 | J21: 1520.46 | K21: 8 | L21: 7 | M21: 2026-10-15T05:04:54Z | N21: 2026-10-15T05:12:30Z | O21: 457 | P21: 0 | Q21: 0 | R21: 260289.35 | S21: 15008 | T21: 2153
A22: 21 | B22: 6qtsui7ntgkDyB1YzokZAmDeBRTe1GcWTpT76uKpPBPu | C22: axiom | E22: 1110.46 | F22: 0 | G22: 1110.46 | H22: 582.09 | I22: 190.77 | J22: 1301.24 | K22: 9 | L22: 39 | M22: 2026-10-15T04:58:38Z | N22: 2026-10-15T05:19:50Z | O22: 1272 | P22: 0 | Q22: 0 | R22: 90494.21 | S22: 32400 | T22: 6562
A23: 22 | B23: 3YRuiSpoPpxjrdZMTQvXVK2v4Cjdy6ZTzV5NpxSaW4gQ | C23: axiom;bloom | E23: 1054.96 | F23: 0 | G23: 1054.96 | H23: 0 | I23: 0 | J23: 1054.96 | K23: 0 | L23: 9 | M23: 2026-10-15T05:10:48Z | N23: 2026-10-15T05:12:11Z | P23: 0 | Q23: 0 | R23: 235449.04 | S23: 28002 | T23: 6151
A24: 23 | B24: FSHXkmt8TPdwE3Qe9xxpX7QFVfJC4YfdDsCzZmM2G2Wi | C24: axiom;sns | D24: neverforever.sol | E24: 1017.8 | F24: 0 | G24: 1017.8 | H24: 57.92 | I24: 1757.29 | J24: 2775.09 | K24: 14 | L24: 34 | M24: 2026-10-15T05:05:04Z | N24: 2026-10-15T05:48:23Z | O24: 2598 | P24: 0 | Q24: 0 | R24: 136418.25 | S24: 15551 | T24: 2035
A25: 24 | B25: 9NVFdRNEcreYDZqJAhennP2tTzaiNC2p9h9HWTdjLBuB | C25: axiom;fomo | E25: 1006.62 | F25: 0 | G25: 1006.62 | H25: 40.32 | I25: 2496.63 | J25: 3503.26 | K25: 6 | L25: 4 | M25: 2026-10-15T05:26:15Z | N25: 2026-10-15T05:58:19Z | O25: 1924 | P25: 0 | Q25: 0 | R25: 57866.11 | S25: 14571 | T25: 3789
A26: 25 | B26: DFvoyXaNPANK9ENGekE88FALjt2CMHWspZKTg62hJJ1Z | C26: fomo | E26: 998.59 | F26: 0 | G26: 998.59 | H26: 96.11 | I26: 1038.98 | J26: 2037.58 | K26: 1 | L26: 1 | M26: 2026-10-15T05:14:58Z | N26: 2026-10-15T05:21:51Z | O26: 413 | P26: 0 | Q26: 0 | R26: 2038.85 | S26: 32 | T26: 12
A27: 26 | B27: DEdwtjvCs6dSadA8b6EQwCP95mXebTqMDK6wh13xhdpR | C27: terminal;axiom | E27: 989.4 | F27: 0 | G27: 989.4 | H27: 154.02 | I27: 642.38 | J27: 1631.78 | K27: 3 | L27: 9 | M27: 2026-10-15T05:00:00Z | N27: 2026-10-15T05:10:49Z | O27: 650 | P27: 0 | Q27: 0 | R27: 171795.89 | S27: 43891 | T27: 19105
A28: 27 | B28: GNJmDgfMeVD5gvfSFSyJzCXnFNSxM5xhnzSToTQ4YbUz | C28: axiom | E28: 983.76 | F28: 0 | G28: 983.76 | H28: 75.58 | I28: 1301.58 | J28: 2285.34 | K28: 7 | L28: 15 | M28: 2026-10-15T05:45:05Z | N28: 2026-10-15T05:59:12Z | O28: 847 | P28: 0 | Q28: 0 | R28: 19978.24 | S28: 6014 | T28: 1145
A29: 28 | B29: AVjEtg2ECYKXYeqdRQXvaaAZBjfTjYuSMTR4WLhKoeQN | C29: kol;axiom | D29: Putrick | E29: 970.55 | F29: 0 | G29: 970.55 | H29: 32.71 | I29: 2967 | J29: 3937.54 | K29: 25 | L29: 14 | M29: 2026-10-15T05:08:13Z | N29: 2026-10-15T05:43:18Z | O29: 2105 | P29: 0 | Q29: 0 | R29: 390230.04 | S29: 87305 | T29: 24806
A30: 29 | B30: HYSq1KBAvqWpEv1pCbV31muKM1za5A1WSHGdiVLUoNhb | C30: terminal;axiom;pumpfun-app | D30: Apex | E30: 923.91 | F30: 0 | G30: 923.91 | H30: 86.27 | I30: 1071.02 | J30: 1994.93 | K30: 6 | L30: 14 | M30: 2026-10-15T05:03:22Z | N30: 2026-10-15T05:10:53Z | O30: 451 | P30: 0 | Q30: 0 | R30: 349210.29 | S30: 34599 | T30: 5508
A31: 30 | B31: 5d3HHrbc9Ho48jibqiVM5GJi7cuL3p17SiJkc1y8qrQ3 | C31: axiom | E31: 916.13 | F31: 0 | G31: 916.13 | H31: 903.4 | I31: 101.41 | J31: 1017.54 | K31: 1 | L31: 28 | M31: 2026-10-15T05:02:05Z | N31: 2026-10-15T05:22:19Z | O31: 1214 | P31: 0 | Q31: 0 | R31: 792.09 | S31: 813 | T31: 200
A32: 31 | B32: BWiJ8aqkhSQx55KA4mB8KXv82ga2972tLtgpAZiuocrU | C32: terminal;axiom | E32: 914.37 | F32: 0 | G32: 914.37 | H32: 146.68 | I32: 623.39 | J32: 1537.76 | K32: 3 | L32: 9 | M32: 2026-10-15T05:00:00Z | N32: 2026-10-15T05:10:49Z | O32: 650 | P32: 0 | Q32: 0 | R32: 96695.12 | S32: 19459 | T32: 8062
A33: 32 | B33: 6AKrfdeLdgsR1NJjSEih7rajxv8AQvrkmmhn9HMuqrcf | C33: potential_bot | E33: 898.4 | F33: 0 | G33: 898.4 | H33: 0 | I33: 0 | J33: 898.4 | K33: 0 | L33: 5 | M33: 2026-10-15T04:58:40Z | N33: 2026-10-15T05:03:05Z | P33: 0 | Q33: 0 | R33: 830698.26 | S33: 5613 | T33: 3629
A34: 33 | B34: 9eUx1DGDzAQuEXR9pSR9u3QworFT8TRgFJatcCiXNURS | C34: fomo | D34: Tristan | E34: 883.38 | F34: 0 | G34: 883.38 | H34: 62.13 | I34: 1421.86 | J34: 2305.24 | K34: 2 | L34: 2 | M34: 2026-10-15T05:07:19Z | N34: 2026-10-15T05:21:40Z | O34: 862 | P34: 0 | Q34: 0 | R34: -9146.81 | S34: 446 | T34: 115
A35: 34 | B35: x2zQL7mx6YFuw31gsWJySDfoYjz9YPU6wXMTzuWkuHU | C35: axiom | E35: 867.83 | F35: 0 | G35: 867.83 | H35: 115.55 | I35: 751.02 | J35: 1618.85 | K35: 14 | L35: 17 | M35: 2026-10-15T05:02:49Z | N35: 2026-10-15T05:40:50Z | O35: 2281 | P35: 0 | Q35: 0 | R35: 31688.28 | S35: 5099 | T35: 874
A36: 35 | B36: BB1x5SKrqBmKk6PvwTtBi6J7knjVmTjXXp7azj6eTGRu | C36: axiom | E36: 860.43 | F36: 0 | G36: 860.43 | H36: 169.76 | I36: 506.85 | J36: 1367.28 | K36: 1 | L36: 13 | M36: 2026-10-15T05:05:04Z | N36: 2026-10-15T05:12:53Z | O36: 468 | P36: 0 | Q36: 0 | R36: 33748.8 | S36: 4187 | T36: 1186
A37: 36 | B37: 39q2g5tTQn9n7KnuapzwS2smSx3NGYqBoea11tBjsGEt | C37: kol;gmgn;photon | D37: Walta | E37: 846.26 | F37: 0 | G37: 846.26 | H37: 83.08 | I37: 1018.67 | J37: 1864.92 | K37: 2 | L37: 3 | M37: 2026-10-15T05:10:37Z | N37: 2026-10-15T05:18:59Z | O37: 502 | P37: 0 | Q37: 0 | R37: 743750.32 | S37: 26059 | T37: 6429
A38: 37 | B38: 3muYDxhtxKLvBvmwxo2DNVNsjG38LLWMmvhuewvyYPnK | C38: axiom | E38: 839.02 | F38: 0 | G38: 839.02 | H38: 165.68 | I38: 506.42 | J38: 1345.45 | K38: 1 | L38: 6 | M38: 2026-10-15T05:05:04Z | N38: 2026-10-15T05:12:23Z | O38: 438 | P38: 0 | Q38: 0 | R38: 17750.29 | S38: 4156 | T38: 1201
A39: 38 | B39: 8WKJJeDBrK8TPtqZXTXXqbsJV6UoXZx9UQBrPf1QqUvG | C39: axiom;photon | E39: 822.53 | F39: 0 | G39: 822.53 | H39: 201.3 | I39: 408.61 | J39: 1231.14 | K39: 2 | L39: 5 | M39: 2026-10-15T05:08:01Z | N39: 2026-10-15T05:15:08Z | O39: 427 | P39: 0 | Q39: 0 | R39: 150143.56 | S39: 2390 | T39: 794
A40: 39 | B40: CTVa2f63dtzf3tx7NBPe3bhV2a5SYm5UiyYSQmV3DDBD | C40: fomo | D40: ///Steki🧲 | E40: 786.29 | F40: 0 | G40: 786.29 | H40: 39.37 | I40: 1997.01 | J40: 2783.3 | K40: 1 | L40: 3 | M40: 2026-10-15T05:12:59Z | N40: 2026-10-15T05:34:38Z | O40: 1300 | P40: 0 | Q40: 0 | R40: 10644.3 | S40: 642 | T40: 134
...

Sheet GMGN
A1: Tidak ada data dari GMGN.
A2: Status: gagal
A3: Error: GMGN API error (HTTP 401): code=401 AUTH_TIMESTAMP_EXPIRED timestamp expired Check GMGN_API_KEY (the API key, not the private key). GMGN only works over IPv4, so disable IPv6 if the key is correct, and make sure this PC's clock is accurate (the server allows about 5 seconds of drift).

Sheet Log
A1: Log run
A3: Lingkungan dan parameter
A4: Suite | B4: 1.0.0
A5: Python | B5: 3.14.6
A6: Sistem operasi | B6: Windows-11-10.0.22000-SP0
A7: openpyxl | B7: 3.1.5
A8: Mint | B8: CoHH4XfCpEcAuQga8iSr3hCta3vyFxYW6BtQRAV3xQMo
A9: Snapshot (UTC) | B9: 2026-10-15 06:26:26
A10: Batas waktu per sumber (detik) | B10: 120
A11: Arsip raw JSON diminta | B11: ya
A12: Ambang awal selisih (USD / relatif) | B12: 10 / 25%
A14: Proses per sumber (kunci API tidak pernah dicatat; setiap proses hanya menerima kuncinya sendiri)
A15: Sumber | B15: Status | C15: Kode keluar | D15: Perintah | E15: Folder kerja | F15: Mulai (UTC) | G15: Selesai (UTC) | H15: Durasi (dtk) | I15: Berkas | J15: Catatan
A16: Vybe | B16: ok | C16: 0 | D16: C:\Python314\python.exe "D:\V 1.1 - backup\V1.2\top-trader-suite\vybe\main.py" CoHH4XfCpEcAuQga8iSr3hCta3vyFxYW6BtQRAV3xQMo | E16: D:\V 1.1 - backup\V1.2\top-trader-suite\output\_raw\CoHH4XfC_20261015_062626\vybe | F16: 2026-10-15 06:26:26 | G16: 2026-10-15 06:26:32 | H16: 6 | I16: top_traders_CoHH4XfCpEcAuQga8iSr3hCta3vyFxYW6BtQRAV3xQMo_20261015_062631.csv
A17: SolanaTracker | B17: ok | C17: 0 | D17: C:\Python314\python.exe "D:\V 1.1 - backup\V1.2\top-trader-suite\solanatracker\main.py" CoHH4XfCpEcAuQga8iSr3hCta3vyFxYW6BtQRAV3xQMo --raw | E17: D:\V 1.1 - backup\V1.2\top-trader-suite\output\_raw\CoHH4XfC_20261015_062626\solanatracker | F17: 2026-10-15 06:26:26 | G17: 2026-10-15 06:26:32 | H17: 6.1 | I17: solanatracker_top_traders_CoHH4XfCpEcAuQga8iSr3hCta3vyFxYW6BtQRAV3xQMo_20261015_062630.csv, solanatracker_top_traders_CoHH4XfCpEcAuQga8iSr3hCta3vyFxYW6BtQRAV3xQMo_20261015_062630.raw.json
A18: GMGN | B18: gagal | C18: 1 | D18: C:\Python314\python.exe "D:\V 1.1 - backup\V1.2\top-trader-suite\gmgn\main.py" CoHH4XfCpEcAuQga8iSr3hCta3vyFxYW6BtQRAV3xQMo --raw | E18: D:\V 1.1 - backup\V1.2\top-trader-suite\output\_raw\CoHH4XfC_20261015_062626\gmgn | F18: 2026-10-15 06:26:26 | G18: 2026-10-15 06:26:29 | H18: 3.4 | J18: Error: GMGN API error (HTTP 401): code=401 AUTH_TIMESTAMP_EXPIRED timestamp expired Check GMGN_API_KEY (the API key, not the private key). GMGN only works over IPv4, so disable IPv6 if the key is correct, and make sure this PC's clock is accurate (the server allows about 5 seconds of drift).
A20: Keluaran proses (dipotong bila panjang)
A21: Vybe stdout | B21: Created output\top_traders_CoHH4XfCpEcAuQga8iSr3hCta3vyFxYW6BtQRAV3xQMo_20261015_062631.csv (100 traders)
A22: SolanaTracker stdout | B22: Created output\solanatracker_top_traders_CoHH4XfCpEcAuQga8iSr3hCta3vyFxYW6BtQRAV3xQMo_20261015_062630.csv (100 traders) - NIHILISM (Nihilism)
A23: GMGN stderr | B23: Error: GMGN API error (HTTP 401): code=401 AUTH_TIMESTAMP_EXPIRED timestamp expired Check GMGN_API_KEY (the API key, not the private key). GMGN only works over IPv4, so disable IPv6 if the key is correct, and make sure this PC's clock is accurate (the server allows about 5 seconds of drift).
A25: Sidik jari kode (SHA-256, 16 karakter pertama) - untuk memastikan versi kode yang dijalankan
A26: Sumber | B26: Berkas | C26: SHA-256
A27: Vybe | B27: main.py | C27: 249919e2e3f83dbb
A28: Vybe | B28: vybe.py | C28: f88ad250cbb9186d
A29: Vybe | B29: csv_writer.py | C29: 56cd7548f0763d3f
A30: SolanaTracker | B30: main.py | C30: 87e2df6587fb4f35
A31: SolanaTracker | B31: solanatracker.py | C31: 24dc000755d40d1b
A32: SolanaTracker | B32: csv_writer.py | C32: 95665c59391c53c0
A33: GMGN | B33: main.py | C33: 1e1e9abfe03032c3
A34: GMGN | B34: gmgn.py | C34: 9372cc27b33b6186
A35: GMGN | B35: csv_writer.py | C35: c23305386940d1ab
